package main.extremeblocks.worldgen;

import main.com.hk.eb.util.Builder;
import main.com.hk.eb.util.Builder.ChestType;
import main.com.hk.eb.util.Rand;
import main.extremeblocks.worldgen.GenManager.Gen;
import net.minecraft.block.BlockLiquid;
import net.minecraft.init.Blocks;
import net.minecraft.world.biome.BiomeGenBase;
import net.minecraft.world.biome.BiomeGenBase.TempCategory;

@Gen(chance = 3, name = "Sunken Ship")
public class GenSunkenShip extends Generation
{
	@Override
	public boolean canGenerateAt(Builder helper)
	{
		for (int i = -12; i < 13; i++)
		{
			for (int j = 0; j < 14; j++)
			{
				for (int k = 3; k < -4; k++)
				{
					if (helper.getBlockAt(i, j, k) instanceof BlockLiquid)
					{
						continue;
					}
					return false;
				}
			}
		}
		return isRightBiome(helper.getBiomeAtSpot()) && helper.rand.nextInt(40) == 0;
	}

	public boolean isRightBiome(BiomeGenBase biome)
	{
		return biome.getTempCategory() == TempCategory.OCEAN;
	}

	@Override
	public boolean generateStructure(Builder helper)
	{
		helper.setBlockToAir(-1, 2, 10);
		helper.setBlockToAir(-1, 2, 12);
		helper.setBlockToAir(-1, 2, 9);
		helper.setBlockToAir(-1, 3, -13);
		helper.setBlockToAir(-1, 3, 10);
		helper.setBlockToAir(-1, 3, 11);
		helper.setBlockToAir(-1, 3, 12);
		helper.setBlockToAir(-1, 3, 9);
		helper.setBlockToAir(-2, 3, 10);
		helper.setBlockToAir(-2, 3, 11);
		helper.setBlockToAir(-2, 3, 12);
		helper.setBlockToAir(-2, 3, 9);
		helper.setBlockToAir(-3, 3, 10);
		helper.setBlockToAir(-3, 3, 11);
		helper.setBlockToAir(0, 2, 10);
		helper.setBlockToAir(0, 2, 12);
		helper.setBlockToAir(0, 2, 9);
		helper.setBlockToAir(0, 3, -1);
		helper.setBlockToAir(0, 3, -11);
		helper.setBlockToAir(0, 3, -12);
		helper.setBlockToAir(0, 3, -13);
		helper.setBlockToAir(0, 3, -14);
		helper.setBlockToAir(0, 3, -15);
		helper.setBlockToAir(0, 3, -3);
		helper.setBlockToAir(0, 3, -4);
		helper.setBlockToAir(0, 3, -5);
		helper.setBlockToAir(0, 3, -6);
		helper.setBlockToAir(0, 3, -7);
		helper.setBlockToAir(0, 3, -8);
		helper.setBlockToAir(0, 3, -9);
		helper.setBlockToAir(0, 3, 0);
		helper.setBlockToAir(0, 3, 1);
		helper.setBlockToAir(0, 3, 10);
		helper.setBlockToAir(0, 3, 11);
		helper.setBlockToAir(0, 3, 12);
		helper.setBlockToAir(0, 3, 2);
		helper.setBlockToAir(0, 3, 3);
		helper.setBlockToAir(0, 3, 4);
		helper.setBlockToAir(0, 3, 5);
		helper.setBlockToAir(0, 3, 6);
		helper.setBlockToAir(0, 3, 7);
		helper.setBlockToAir(0, 3, 9);
		helper.setBlockToAir(1, 10, -10);
		helper.setBlockToAir(1, 10, -2);
		helper.setBlockToAir(1, 11, -1);
		helper.setBlockToAir(1, 11, -10);
		helper.setBlockToAir(1, 11, -11);
		helper.setBlockToAir(1, 11, -2);
		helper.setBlockToAir(1, 12, -1);
		helper.setBlockToAir(1, 12, -10);
		helper.setBlockToAir(1, 12, -11);
		helper.setBlockToAir(1, 12, -2);
		helper.setBlockToAir(1, 13, -1);
		helper.setBlockToAir(1, 13, -10);
		helper.setBlockToAir(1, 13, -11);
		helper.setBlockToAir(1, 13, -2);
		helper.setBlockToAir(1, 14, -1);
		helper.setBlockToAir(1, 14, -10);
		helper.setBlockToAir(1, 14, -11);
		helper.setBlockToAir(1, 14, -2);
		helper.setBlockToAir(1, 15, -10);
		helper.setBlockToAir(1, 15, -2);
		helper.setBlockToAir(1, 2, 12);
		helper.setBlockToAir(1, 3, -1);
		helper.setBlockToAir(1, 3, -10);
		helper.setBlockToAir(1, 3, -11);
		helper.setBlockToAir(1, 3, -12);
		helper.setBlockToAir(1, 3, -13);
		helper.setBlockToAir(1, 3, -14);
		helper.setBlockToAir(1, 3, -15);
		helper.setBlockToAir(1, 3, -16);
		helper.setBlockToAir(1, 3, -2);
		helper.setBlockToAir(1, 3, -3);
		helper.setBlockToAir(1, 3, -4);
		helper.setBlockToAir(1, 3, -5);
		helper.setBlockToAir(1, 3, -6);
		helper.setBlockToAir(1, 3, -7);
		helper.setBlockToAir(1, 3, -8);
		helper.setBlockToAir(1, 3, -9);
		helper.setBlockToAir(1, 3, 0);
		helper.setBlockToAir(1, 3, 1);
		helper.setBlockToAir(1, 3, 11);
		helper.setBlockToAir(1, 3, 12);
		helper.setBlockToAir(1, 3, 2);
		helper.setBlockToAir(1, 3, 3);
		helper.setBlockToAir(1, 3, 4);
		helper.setBlockToAir(1, 3, 5);
		helper.setBlockToAir(1, 3, 6);
		helper.setBlockToAir(1, 3, 7);
		helper.setBlockToAir(1, 5, -10);
		helper.setBlockToAir(1, 5, -2);
		helper.setBlockToAir(1, 5, 3);
		helper.setBlockToAir(1, 5, 5);
		helper.setBlockToAir(1, 5, 6);
		helper.setBlockToAir(1, 5, 7);
		helper.setBlockToAir(1, 5, 8);
		helper.setBlockToAir(1, 6, -10);
		helper.setBlockToAir(1, 6, -2);
		helper.setBlockToAir(1, 6, 5);
		helper.setBlockToAir(1, 6, 6);
		helper.setBlockToAir(1, 6, 7);
		helper.setBlockToAir(1, 6, 8);
		helper.setBlockToAir(1, 6, 9);
		helper.setBlockToAir(1, 7, -10);
		helper.setBlockToAir(1, 7, -2);
		helper.setBlockToAir(1, 7, 5);
		helper.setBlockToAir(1, 7, 6);
		helper.setBlockToAir(1, 7, 7);
		helper.setBlockToAir(1, 7, 8);
		helper.setBlockToAir(1, 7, 9);
		helper.setBlockToAir(2, 10, -1);
		helper.setBlockToAir(2, 10, -10);
		helper.setBlockToAir(2, 10, -11);
		helper.setBlockToAir(2, 10, -2);
		helper.setBlockToAir(2, 11, -1);
		helper.setBlockToAir(2, 11, -10);
		helper.setBlockToAir(2, 11, -11);
		helper.setBlockToAir(2, 11, -2);
		helper.setBlockToAir(2, 12, -1);
		helper.setBlockToAir(2, 12, -10);
		helper.setBlockToAir(2, 12, -11);
		helper.setBlockToAir(2, 12, -2);
		helper.setBlockToAir(2, 13, -1);
		helper.setBlockToAir(2, 13, -10);
		helper.setBlockToAir(2, 13, -11);
		helper.setBlockToAir(2, 13, -2);
		helper.setBlockToAir(2, 14, -1);
		helper.setBlockToAir(2, 14, -10);
		helper.setBlockToAir(2, 14, -11);
		helper.setBlockToAir(2, 14, -2);
		helper.setBlockToAir(2, 15, -1);
		helper.setBlockToAir(2, 15, -10);
		helper.setBlockToAir(2, 15, -11);
		helper.setBlockToAir(2, 15, -2);
		helper.setBlockToAir(2, 2, 12);
		helper.setBlockToAir(2, 3, -1);
		helper.setBlockToAir(2, 3, -10);
		helper.setBlockToAir(2, 3, -11);
		helper.setBlockToAir(2, 3, -12);
		helper.setBlockToAir(2, 3, -2);
		helper.setBlockToAir(2, 3, -3);
		helper.setBlockToAir(2, 3, -4);
		helper.setBlockToAir(2, 3, -5);
		helper.setBlockToAir(2, 3, -7);
		helper.setBlockToAir(2, 3, -8);
		helper.setBlockToAir(2, 3, -9);
		helper.setBlockToAir(2, 3, 0);
		helper.setBlockToAir(2, 3, 1);
		helper.setBlockToAir(2, 3, 11);
		helper.setBlockToAir(2, 3, 12);
		helper.setBlockToAir(2, 3, 2);
		helper.setBlockToAir(2, 3, 3);
		helper.setBlockToAir(2, 3, 4);
		helper.setBlockToAir(2, 3, 5);
		helper.setBlockToAir(2, 3, 6);
		helper.setBlockToAir(2, 3, 7);
		helper.setBlockToAir(2, 3, 8);
		helper.setBlockToAir(2, 5, -10);
		helper.setBlockToAir(2, 5, -2);
		helper.setBlockToAir(2, 5, 3);
		helper.setBlockToAir(2, 5, 5);
		helper.setBlockToAir(2, 5, 6);
		helper.setBlockToAir(2, 5, 7);
		helper.setBlockToAir(2, 6, -10);
		helper.setBlockToAir(2, 6, -2);
		helper.setBlockToAir(2, 6, 3);
		helper.setBlockToAir(2, 6, 5);
		helper.setBlockToAir(2, 6, 6);
		helper.setBlockToAir(2, 6, 7);
		helper.setBlockToAir(2, 6, 8);
		helper.setBlockToAir(2, 6, 9);
		helper.setBlockToAir(2, 7, -10);
		helper.setBlockToAir(2, 7, -2);
		helper.setBlockToAir(2, 7, 5);
		helper.setBlockToAir(2, 7, 6);
		helper.setBlockToAir(2, 7, 7);
		helper.setBlockToAir(2, 7, 8);
		helper.setBlockToAir(2, 7, 9);
		helper.setBlockToAir(3, 10, -10);
		helper.setBlockToAir(3, 10, -2);
		helper.setBlockToAir(3, 11, -1);
		helper.setBlockToAir(3, 11, -10);
		helper.setBlockToAir(3, 11, -11);
		helper.setBlockToAir(3, 11, -2);
		helper.setBlockToAir(3, 12, -1);
		helper.setBlockToAir(3, 12, -10);
		helper.setBlockToAir(3, 12, -11);
		helper.setBlockToAir(3, 12, -2);
		helper.setBlockToAir(3, 13, -1);
		helper.setBlockToAir(3, 13, -10);
		helper.setBlockToAir(3, 13, -11);
		helper.setBlockToAir(3, 13, -2);
		helper.setBlockToAir(3, 14, -1);
		helper.setBlockToAir(3, 14, -10);
		helper.setBlockToAir(3, 14, -11);
		helper.setBlockToAir(3, 14, -2);
		helper.setBlockToAir(3, 15, -10);
		helper.setBlockToAir(3, 15, -2);
		helper.setBlockToAir(3, 2, 12);
		helper.setBlockToAir(3, 3, -1);
		helper.setBlockToAir(3, 3, -10);
		helper.setBlockToAir(3, 3, -11);
		helper.setBlockToAir(3, 3, -12);
		helper.setBlockToAir(3, 3, -13);
		helper.setBlockToAir(3, 3, -14);
		helper.setBlockToAir(3, 3, -15);
		helper.setBlockToAir(3, 3, -16);
		helper.setBlockToAir(3, 3, -2);
		helper.setBlockToAir(3, 3, -3);
		helper.setBlockToAir(3, 3, -4);
		helper.setBlockToAir(3, 3, -5);
		helper.setBlockToAir(3, 3, -6);
		helper.setBlockToAir(3, 3, -7);
		helper.setBlockToAir(3, 3, -8);
		helper.setBlockToAir(3, 3, -9);
		helper.setBlockToAir(3, 3, 0);
		helper.setBlockToAir(3, 3, 1);
		helper.setBlockToAir(3, 3, 11);
		helper.setBlockToAir(3, 3, 12);
		helper.setBlockToAir(3, 3, 2);
		helper.setBlockToAir(3, 3, 3);
		helper.setBlockToAir(3, 3, 4);
		helper.setBlockToAir(3, 3, 5);
		helper.setBlockToAir(3, 3, 6);
		helper.setBlockToAir(3, 3, 7);
		helper.setBlockToAir(3, 3, 8);
		helper.setBlockToAir(3, 5, -10);
		helper.setBlockToAir(3, 5, -2);
		helper.setBlockToAir(3, 5, 3);
		helper.setBlockToAir(3, 5, 5);
		helper.setBlockToAir(3, 5, 6);
		helper.setBlockToAir(3, 5, 7);
		helper.setBlockToAir(3, 5, 8);
		helper.setBlockToAir(3, 6, -10);
		helper.setBlockToAir(3, 6, -2);
		helper.setBlockToAir(3, 6, 3);
		helper.setBlockToAir(3, 6, 5);
		helper.setBlockToAir(3, 6, 6);
		helper.setBlockToAir(3, 6, 7);
		helper.setBlockToAir(3, 6, 8);
		helper.setBlockToAir(3, 6, 9);
		helper.setBlockToAir(3, 7, -10);
		helper.setBlockToAir(3, 7, -2);
		helper.setBlockToAir(3, 7, 5);
		helper.setBlockToAir(3, 7, 6);
		helper.setBlockToAir(3, 7, 7);
		helper.setBlockToAir(3, 7, 8);
		helper.setBlockToAir(3, 7, 9);
		helper.setBlockToAir(4, 2, 10);
		helper.setBlockToAir(4, 2, 12);
		helper.setBlockToAir(4, 2, 9);
		helper.setBlockToAir(4, 3, -1);
		helper.setBlockToAir(4, 3, -11);
		helper.setBlockToAir(4, 3, -12);
		helper.setBlockToAir(4, 3, -13);
		helper.setBlockToAir(4, 3, -14);
		helper.setBlockToAir(4, 3, -15);
		helper.setBlockToAir(4, 3, -3);
		helper.setBlockToAir(4, 3, -4);
		helper.setBlockToAir(4, 3, -5);
		helper.setBlockToAir(4, 3, -6);
		helper.setBlockToAir(4, 3, -7);
		helper.setBlockToAir(4, 3, -8);
		helper.setBlockToAir(4, 3, -9);
		helper.setBlockToAir(4, 3, 1);
		helper.setBlockToAir(4, 3, 10);
		helper.setBlockToAir(4, 3, 11);
		helper.setBlockToAir(4, 3, 12);
		helper.setBlockToAir(4, 3, 2);
		helper.setBlockToAir(4, 3, 3);
		helper.setBlockToAir(4, 3, 4);
		helper.setBlockToAir(4, 3, 5);
		helper.setBlockToAir(4, 3, 6);
		helper.setBlockToAir(4, 3, 7);
		helper.setBlockToAir(4, 3, 9);
		helper.setBlockToAir(5, 2, 10);
		helper.setBlockToAir(5, 2, 12);
		helper.setBlockToAir(5, 2, 9);
		helper.setBlockToAir(5, 3, 10);
		helper.setBlockToAir(5, 3, 11);
		helper.setBlockToAir(5, 3, 12);
		helper.setBlockToAir(5, 3, 9);
		helper.setBlockToAir(6, 3, 10);
		helper.setBlockToAir(6, 3, 11);
		helper.setBlockToAir(6, 3, 12);
		helper.setBlockToAir(6, 3, 9);
		helper.setBlockToAir(7, 3, 10);
		helper.setBlockToAir(7, 3, 11);
		helper.setBlock(Blocks.fence, 0, 23, -4);
		helper.setBlock(Blocks.fence, 0, 23, -5);
		helper.setBlock(Blocks.fence, 0, 23, -6);
		helper.setBlock(Blocks.fence, 0, 23, -7);
		helper.setBlock(Blocks.fence, 0, 23, -8);
		helper.setBlock(Blocks.fence, 1, 23, -4);
		helper.setBlock(Blocks.fence, 1, 23, -8);
		helper.setBlock(Blocks.fence, 2, 23, -4);
		helper.setBlock(Blocks.fence, 2, 23, -8);
		helper.setBlock(Blocks.fence, 3, 23, -4);
		helper.setBlock(Blocks.fence, 3, 23, -8);
		helper.setBlock(Blocks.fence, 4, 23, -4);
		helper.setBlock(Blocks.fence, 4, 23, -5);
		helper.setBlock(Blocks.fence, 4, 23, -6);
		helper.setBlock(Blocks.fence, 4, 23, -7);
		helper.setBlock(Blocks.fence, 4, 23, -8);
		helper.setBlock(Blocks.log, 0, 10, -10);
		helper.setBlock(Blocks.log, 0, 10, -2);
		helper.setBlock(Blocks.log, 0, 11, -10);
		helper.setBlock(Blocks.log, 0, 11, -2);
		helper.setBlock(Blocks.log, 0, 12, -10);
		helper.setBlock(Blocks.log, 0, 12, -2);
		helper.setBlock(Blocks.log, 0, 13, -10);
		helper.setBlock(Blocks.log, 0, 13, -2);
		helper.setBlock(Blocks.log, 0, 14, -10);
		helper.setBlock(Blocks.log, 0, 14, -2);
		helper.setBlock(Blocks.log, 0, 15, -10);
		helper.setBlock(Blocks.log, 0, 15, -2);
		helper.setBlock(Blocks.log, 0, 16, -10);
		helper.setBlock(Blocks.log, 0, 16, -2);
		helper.setBlock(Blocks.log, 0, 2, -10);
		helper.setBlock(Blocks.log, 0, 2, -2);
		helper.setBlock(Blocks.log, 0, 22, -4, 8);
		helper.setBlock(Blocks.log, 0, 22, -5, 4);
		helper.setBlock(Blocks.log, 0, 22, -6, 8);
		helper.setBlock(Blocks.log, 0, 22, -7, 4);
		helper.setBlock(Blocks.log, 0, 22, -8, 8);
		helper.setBlock(Blocks.log, 0, 3, -10);
		helper.setBlock(Blocks.log, 0, 3, -2);
		helper.setBlock(Blocks.log, 0, 4, -10);
		helper.setBlock(Blocks.log, 0, 4, -2);
		helper.setBlock(Blocks.log, 0, 5, -10);
		helper.setBlock(Blocks.log, 0, 5, -2);
		helper.setBlock(Blocks.log, 0, 6, -10);
		helper.setBlock(Blocks.log, 0, 6, -2);
		helper.setBlock(Blocks.log, 0, 7, -10);
		helper.setBlock(Blocks.log, 0, 7, -2);
		helper.setBlock(Blocks.log, 0, 8, -10);
		helper.setBlock(Blocks.log, 0, 8, -2);
		helper.setBlock(Blocks.log, 0, 9, -10);
		helper.setBlock(Blocks.log, 0, 9, -2);
		helper.setBlock(Blocks.log, 1, 16, -10, 4);
		helper.setBlock(Blocks.log, 1, 16, -2, 4);
		helper.setBlock(Blocks.log, 1, 20, -6);
		helper.setBlock(Blocks.log, 1, 21, -5);
		helper.setBlock(Blocks.log, 1, 21, -6);
		helper.setBlock(Blocks.log, 1, 21, -7);
		helper.setBlock(Blocks.log, 1, 22, -4, 4);
		helper.setBlock(Blocks.log, 1, 22, -5, 8);
		helper.setBlock(Blocks.log, 1, 22, -6, 4);
		helper.setBlock(Blocks.log, 1, 22, -7, 8);
		helper.setBlock(Blocks.log, 1, 22, -8, 4);
		helper.setBlock(Blocks.log, 1, 26, -6, 4);
		helper.setBlock(Blocks.log, 1, 9, -10, 4);
		helper.setBlock(Blocks.log, 1, 9, -2, 4);
		helper.setBlock(Blocks.log, 2, 10, -6);
		helper.setBlock(Blocks.log, 2, 11, -6);
		helper.setBlock(Blocks.log, 2, 12, -6);
		helper.setBlock(Blocks.log, 2, 13, -6);
		helper.setBlock(Blocks.log, 2, 14, -6);
		helper.setBlock(Blocks.log, 2, 15, -6);
		helper.setBlock(Blocks.log, 2, 16, -10, 4);
		helper.setBlock(Blocks.log, 2, 16, -2, 4);
		helper.setBlock(Blocks.log, 2, 16, -6);
		helper.setBlock(Blocks.log, 2, 17, -6);
		helper.setBlock(Blocks.log, 2, 18, -6);
		helper.setBlock(Blocks.log, 2, 19, -6);
		helper.setBlock(Blocks.log, 2, 2, -6);
		helper.setBlock(Blocks.log, 2, 20, -5);
		helper.setBlock(Blocks.log, 2, 20, -6);
		helper.setBlock(Blocks.log, 2, 21, -5);
		helper.setBlock(Blocks.log, 2, 21, -6);
		helper.setBlock(Blocks.log, 2, 22, -4, 8);
		helper.setBlock(Blocks.log, 2, 22, -6);
		helper.setBlock(Blocks.log, 2, 22, -8, 8);
		helper.setBlock(Blocks.log, 2, 23, -6);
		helper.setBlock(Blocks.log, 2, 24, -6);
		helper.setBlock(Blocks.log, 2, 25, -6);
		helper.setBlock(Blocks.log, 2, 26, -5, 8);
		helper.setBlock(Blocks.log, 2, 26, -6);
		helper.setBlock(Blocks.log, 2, 26, -7, 8);
		helper.setBlock(Blocks.log, 2, 3, -6);
		helper.setBlock(Blocks.log, 2, 4, -6);
		helper.setBlock(Blocks.log, 2, 5, -6);
		helper.setBlock(Blocks.log, 2, 6, -6);
		helper.setBlock(Blocks.log, 2, 7, -6);
		helper.setBlock(Blocks.log, 2, 8, -6);
		helper.setBlock(Blocks.log, 2, 9, -10, 4);
		helper.setBlock(Blocks.log, 2, 9, -2, 4);
		helper.setBlock(Blocks.log, 2, 9, -6);
		helper.setBlock(Blocks.log, 3, 16, -10, 4);
		helper.setBlock(Blocks.log, 3, 16, -2, 4);
		helper.setBlock(Blocks.log, 3, 20, -6);
		helper.setBlock(Blocks.log, 3, 21, -5);
		helper.setBlock(Blocks.log, 3, 21, -6);
		helper.setBlock(Blocks.log, 3, 21, -7);
		helper.setBlock(Blocks.log, 3, 22, -4, 4);
		helper.setBlock(Blocks.log, 3, 22, -5, 8);
		helper.setBlock(Blocks.log, 3, 22, -6, 4);
		helper.setBlock(Blocks.log, 3, 22, -7, 8);
		helper.setBlock(Blocks.log, 3, 22, -8, 4);
		helper.setBlock(Blocks.log, 3, 26, -6, 4);
		helper.setBlock(Blocks.log, 3, 9, -10, 4);
		helper.setBlock(Blocks.log, 3, 9, -2, 4);
		helper.setBlock(Blocks.log, 4, 10, -10);
		helper.setBlock(Blocks.log, 4, 10, -2);
		helper.setBlock(Blocks.log, 4, 11, -10);
		helper.setBlock(Blocks.log, 4, 11, -2);
		helper.setBlock(Blocks.log, 4, 12, -10);
		helper.setBlock(Blocks.log, 4, 12, -2);
		helper.setBlock(Blocks.log, 4, 13, -10);
		helper.setBlock(Blocks.log, 4, 13, -2);
		helper.setBlock(Blocks.log, 4, 14, -10);
		helper.setBlock(Blocks.log, 4, 14, -2);
		helper.setBlock(Blocks.log, 4, 15, -10);
		helper.setBlock(Blocks.log, 4, 15, -2);
		helper.setBlock(Blocks.log, 4, 16, -10);
		helper.setBlock(Blocks.log, 4, 16, -2);
		helper.setBlock(Blocks.log, 4, 2, -10);
		helper.setBlock(Blocks.log, 4, 2, -2);
		helper.setBlock(Blocks.log, 4, 22, -4, 8);
		helper.setBlock(Blocks.log, 4, 22, -5, 4);
		helper.setBlock(Blocks.log, 4, 22, -6, 8);
		helper.setBlock(Blocks.log, 4, 22, -7, 4);
		helper.setBlock(Blocks.log, 4, 22, -8, 8);
		helper.setBlock(Blocks.log, 4, 3, -10);
		helper.setBlock(Blocks.log, 4, 3, -2);
		helper.setBlock(Blocks.log, 4, 4, -10);
		helper.setBlock(Blocks.log, 4, 4, -2);
		helper.setBlock(Blocks.log, 4, 5, -10);
		helper.setBlock(Blocks.log, 4, 5, -2);
		helper.setBlock(Blocks.log, 4, 6, -10);
		helper.setBlock(Blocks.log, 4, 6, -2);
		helper.setBlock(Blocks.log, 4, 7, -10);
		helper.setBlock(Blocks.log, 4, 7, -2);
		helper.setBlock(Blocks.log, 4, 8, -10);
		helper.setBlock(Blocks.log, 4, 8, -2);
		helper.setBlock(Blocks.log, 4, 9, -10);
		helper.setBlock(Blocks.log, 4, 9, -2);
		helper.setBlock(Blocks.oak_stairs, -1, 2, -15, 6);
		helper.setBlock(Blocks.oak_stairs, -1, 5, -15, 3);
		helper.setBlock(Blocks.oak_stairs, -1, 5, -16, 1);
		helper.setBlock(Blocks.oak_stairs, -1, 5, 13, 2);
		helper.setBlock(Blocks.oak_stairs, -1, 7, 10, 3);
		helper.setBlock(Blocks.oak_stairs, -1, 7, 4);
		helper.setBlock(Blocks.oak_stairs, -1, 7, 5);
		helper.setBlock(Blocks.oak_stairs, -1, 7, 6);
		helper.setBlock(Blocks.oak_stairs, -1, 7, 7);
		helper.setBlock(Blocks.oak_stairs, -1, 7, 8);
		helper.setBlock(Blocks.oak_stairs, -1, 7, 9);
		helper.setBlock(Blocks.oak_stairs, -2, 2, -15, 6);
		helper.setBlock(Blocks.oak_stairs, -2, 5, -14, 3);
		helper.setBlock(Blocks.oak_stairs, -2, 5, -15, 1);
		helper.setBlock(Blocks.oak_stairs, -2, 5, 12, 1);
		helper.setBlock(Blocks.oak_stairs, -2, 5, 13, 2);
		helper.setBlock(Blocks.oak_stairs, -3, 2, -10, 4);
		helper.setBlock(Blocks.oak_stairs, -3, 2, -11, 4);
		helper.setBlock(Blocks.oak_stairs, -3, 2, -12, 4);
		helper.setBlock(Blocks.oak_stairs, -3, 2, -13, 4);
		helper.setBlock(Blocks.oak_stairs, -3, 2, -14, 4);
		helper.setBlock(Blocks.oak_stairs, -3, 2, -15, 6);
		helper.setBlock(Blocks.oak_stairs, -3, 2, -3, 4);
		helper.setBlock(Blocks.oak_stairs, -3, 2, -4, 4);
		helper.setBlock(Blocks.oak_stairs, -3, 2, -5, 4);
		helper.setBlock(Blocks.oak_stairs, -3, 2, -6, 4);
		helper.setBlock(Blocks.oak_stairs, -3, 2, -7, 4);
		helper.setBlock(Blocks.oak_stairs, -3, 2, -8, 4);
		helper.setBlock(Blocks.oak_stairs, -3, 2, -9, 4);
		helper.setBlock(Blocks.oak_stairs, -3, 5, -13, 3);
		helper.setBlock(Blocks.oak_stairs, -3, 5, -14, 1);
		helper.setBlock(Blocks.oak_stairs, -3, 5, 12, 2);
		helper.setBlock(Blocks.oak_stairs, -4, 5, -1, 1);
		helper.setBlock(Blocks.oak_stairs, -4, 5, -10, 1);
		helper.setBlock(Blocks.oak_stairs, -4, 5, -11, 1);
		helper.setBlock(Blocks.oak_stairs, -4, 5, -12, 1);
		helper.setBlock(Blocks.oak_stairs, -4, 5, -13, 1);
		helper.setBlock(Blocks.oak_stairs, -4, 5, -2, 1);
		helper.setBlock(Blocks.oak_stairs, -4, 5, -3, 1);
		helper.setBlock(Blocks.oak_stairs, -4, 5, -4, 1);
		helper.setBlock(Blocks.oak_stairs, -4, 5, -5, 1);
		helper.setBlock(Blocks.oak_stairs, -4, 5, -6, 1);
		helper.setBlock(Blocks.oak_stairs, -4, 5, -7, 1);
		helper.setBlock(Blocks.oak_stairs, -4, 5, -8, 1);
		helper.setBlock(Blocks.oak_stairs, -4, 5, -9, 1);
		helper.setBlock(Blocks.oak_stairs, -4, 5, 0, 1);
		helper.setBlock(Blocks.oak_stairs, -4, 5, 1, 1);
		helper.setBlock(Blocks.oak_stairs, -4, 5, 10, 1);
		helper.setBlock(Blocks.oak_stairs, -4, 5, 11, 1);
		helper.setBlock(Blocks.oak_stairs, -4, 5, 12, 2);
		helper.setBlock(Blocks.oak_stairs, -4, 5, 2, 1);
		helper.setBlock(Blocks.oak_stairs, -4, 5, 3, 1);
		helper.setBlock(Blocks.oak_stairs, -4, 5, 4, 1);
		helper.setBlock(Blocks.oak_stairs, -4, 5, 5, 1);
		helper.setBlock(Blocks.oak_stairs, -4, 5, 6, 1);
		helper.setBlock(Blocks.oak_stairs, -4, 5, 7, 1);
		helper.setBlock(Blocks.oak_stairs, -4, 5, 8, 1);
		helper.setBlock(Blocks.oak_stairs, -4, 5, 9, 1);
		helper.setBlock(Blocks.oak_stairs, 0, 5, -16, 3);
		helper.setBlock(Blocks.oak_stairs, 0, 5, -17, 1);
		helper.setBlock(Blocks.oak_stairs, 0, 5, 13, 2);
		helper.setBlock(Blocks.oak_stairs, 0, 5, 5, 7);
		helper.setBlock(Blocks.oak_stairs, 0, 5, 9, 6);
		helper.setBlock(Blocks.oak_stairs, 0, 6, 5, 7);
		helper.setBlock(Blocks.oak_stairs, 0, 6, 9, 6);
		helper.setBlock(Blocks.oak_stairs, 0, 7, 10, 3);
		helper.setBlock(Blocks.oak_stairs, 0, 7, 4, 2);
		helper.setBlock(Blocks.oak_stairs, 0, 7, 5, 7);
		helper.setBlock(Blocks.oak_stairs, 0, 7, 9, 6);
		helper.setBlock(Blocks.oak_stairs, 1, 5, 13, 2);
		helper.setBlock(Blocks.oak_stairs, 1, 5, 9, 6);
		helper.setBlock(Blocks.oak_stairs, 1, 7, 10, 3);
		helper.setBlock(Blocks.oak_stairs, 1, 7, 3, 2);
		helper.setBlock(Blocks.oak_stairs, 1, 7, 4);
		helper.setBlock(Blocks.oak_stairs, 2, 2, -15, 3);
		helper.setBlock(Blocks.oak_stairs, 2, 3, -16, 3);
		helper.setBlock(Blocks.oak_stairs, 2, 3, 10, 7);
		helper.setBlock(Blocks.oak_stairs, 2, 4, -17, 3);
		helper.setBlock(Blocks.oak_stairs, 2, 5, 13, 2);
		helper.setBlock(Blocks.oak_stairs, 2, 5, 8, 3);
		helper.setBlock(Blocks.oak_stairs, 2, 5, 9, 6);
		helper.setBlock(Blocks.oak_stairs, 2, 6, -21, 6);
		helper.setBlock(Blocks.oak_stairs, 2, 7, 10, 3);
		helper.setBlock(Blocks.oak_stairs, 2, 7, 3, 2);
		helper.setBlock(Blocks.oak_stairs, 3, 5, 13, 2);
		helper.setBlock(Blocks.oak_stairs, 3, 5, 9, 6);
		helper.setBlock(Blocks.oak_stairs, 3, 7, 10, 3);
		helper.setBlock(Blocks.oak_stairs, 3, 7, 3, 1);
		helper.setBlock(Blocks.oak_stairs, 3, 7, 4, 1);
		helper.setBlock(Blocks.oak_stairs, 4, 5, -16, 3);
		helper.setBlock(Blocks.oak_stairs, 4, 5, -17);
		helper.setBlock(Blocks.oak_stairs, 4, 5, 13, 2);
		helper.setBlock(Blocks.oak_stairs, 4, 5, 5, 7);
		helper.setBlock(Blocks.oak_stairs, 4, 5, 9, 6);
		helper.setBlock(Blocks.oak_stairs, 4, 6, 5, 7);
		helper.setBlock(Blocks.oak_stairs, 4, 6, 9, 6);
		helper.setBlock(Blocks.oak_stairs, 4, 7, 10, 3);
		helper.setBlock(Blocks.oak_stairs, 4, 7, 4, 2);
		helper.setBlock(Blocks.oak_stairs, 4, 7, 5, 7);
		helper.setBlock(Blocks.oak_stairs, 4, 7, 9, 6);
		helper.setBlock(Blocks.oak_stairs, 5, 5, -15, 3);
		helper.setBlock(Blocks.oak_stairs, 5, 5, -16);
		helper.setBlock(Blocks.oak_stairs, 5, 5, 13, 2);
		helper.setBlock(Blocks.oak_stairs, 5, 7, 10, 1);
		helper.setBlock(Blocks.oak_stairs, 5, 7, 4, 2);
		helper.setBlock(Blocks.oak_stairs, 5, 7, 5, 1);
		helper.setBlock(Blocks.oak_stairs, 5, 7, 6, 1);
		helper.setBlock(Blocks.oak_stairs, 5, 7, 7, 1);
		helper.setBlock(Blocks.oak_stairs, 5, 7, 8, 1);
		helper.setBlock(Blocks.oak_stairs, 5, 7, 9, 1);
		helper.setBlock(Blocks.oak_stairs, 6, 2, -14, 6);
		helper.setBlock(Blocks.oak_stairs, 6, 5, -14, 3);
		helper.setBlock(Blocks.oak_stairs, 6, 5, -15);
		helper.setBlock(Blocks.oak_stairs, 6, 5, 12);
		helper.setBlock(Blocks.oak_stairs, 6, 5, 13, 2);
		helper.setBlock(Blocks.oak_stairs, 7, 2, -10, 5);
		helper.setBlock(Blocks.oak_stairs, 7, 2, -11, 5);
		helper.setBlock(Blocks.oak_stairs, 7, 2, -12, 5);
		helper.setBlock(Blocks.oak_stairs, 7, 2, -13, 5);
		helper.setBlock(Blocks.oak_stairs, 7, 2, -14, 6);
		helper.setBlock(Blocks.oak_stairs, 7, 2, -3, 5);
		helper.setBlock(Blocks.oak_stairs, 7, 2, -4, 5);
		helper.setBlock(Blocks.oak_stairs, 7, 2, -5, 5);
		helper.setBlock(Blocks.oak_stairs, 7, 2, -6, 5);
		helper.setBlock(Blocks.oak_stairs, 7, 2, -7, 5);
		helper.setBlock(Blocks.oak_stairs, 7, 2, -8, 5);
		helper.setBlock(Blocks.oak_stairs, 7, 2, -9, 5);
		helper.setBlock(Blocks.oak_stairs, 7, 5, -13, 3);
		helper.setBlock(Blocks.oak_stairs, 7, 5, -14);
		helper.setBlock(Blocks.oak_stairs, 7, 5, 12, 2);
		helper.setBlock(Blocks.oak_stairs, 8, 5, -1);
		helper.setBlock(Blocks.oak_stairs, 8, 5, -10);
		helper.setBlock(Blocks.oak_stairs, 8, 5, -11);
		helper.setBlock(Blocks.oak_stairs, 8, 5, -12);
		helper.setBlock(Blocks.oak_stairs, 8, 5, -13);
		helper.setBlock(Blocks.oak_stairs, 8, 5, -2);
		helper.setBlock(Blocks.oak_stairs, 8, 5, -3);
		helper.setBlock(Blocks.oak_stairs, 8, 5, -4);
		helper.setBlock(Blocks.oak_stairs, 8, 5, -5);
		helper.setBlock(Blocks.oak_stairs, 8, 5, -6);
		helper.setBlock(Blocks.oak_stairs, 8, 5, -7);
		helper.setBlock(Blocks.oak_stairs, 8, 5, -8);
		helper.setBlock(Blocks.oak_stairs, 8, 5, -9);
		helper.setBlock(Blocks.oak_stairs, 8, 5, 0);
		helper.setBlock(Blocks.oak_stairs, 8, 5, 1);
		helper.setBlock(Blocks.oak_stairs, 8, 5, 10);
		helper.setBlock(Blocks.oak_stairs, 8, 5, 11);
		helper.setBlock(Blocks.oak_stairs, 8, 5, 12, 2);
		helper.setBlock(Blocks.oak_stairs, 8, 5, 2);
		helper.setBlock(Blocks.oak_stairs, 8, 5, 3);
		helper.setBlock(Blocks.oak_stairs, 8, 5, 4);
		helper.setBlock(Blocks.oak_stairs, 8, 5, 5);
		helper.setBlock(Blocks.oak_stairs, 8, 5, 6);
		helper.setBlock(Blocks.oak_stairs, 8, 5, 7);
		helper.setBlock(Blocks.oak_stairs, 8, 5, 8);
		helper.setBlock(Blocks.oak_stairs, 8, 5, 9);
		helper.setBlock(Blocks.planks, -1, 2, -1);
		helper.setBlock(Blocks.planks, -1, 2, -10);
		helper.setBlock(Blocks.planks, -1, 2, -11);
		helper.setBlock(Blocks.planks, -1, 2, -12);
		helper.setBlock(Blocks.planks, -1, 2, -13);
		helper.setBlock(Blocks.planks, -1, 2, -14);
		helper.setBlock(Blocks.planks, -1, 2, -2);
		helper.setBlock(Blocks.planks, -1, 2, -3);
		helper.setBlock(Blocks.planks, -1, 2, -4);
		helper.setBlock(Blocks.planks, -1, 2, -5);
		helper.setBlock(Blocks.planks, -1, 2, -6);
		helper.setBlock(Blocks.planks, -1, 2, -7);
		helper.setBlock(Blocks.planks, -1, 2, -8);
		helper.setBlock(Blocks.planks, -1, 2, -9);
		helper.setBlock(Blocks.planks, -1, 2, 0);
		helper.setBlock(Blocks.planks, -1, 2, 1);
		helper.setBlock(Blocks.planks, -1, 2, 13);
		helper.setBlock(Blocks.planks, -1, 2, 2);
		helper.setBlock(Blocks.planks, -1, 2, 3);
		helper.setBlock(Blocks.planks, -1, 2, 4);
		helper.setBlock(Blocks.planks, -1, 2, 5);
		helper.setBlock(Blocks.planks, -1, 2, 6);
		helper.setBlock(Blocks.planks, -1, 2, 7);
		helper.setBlock(Blocks.planks, -1, 2, 8);
		helper.setBlock(Blocks.planks, -1, 3, -15);
		helper.setBlock(Blocks.planks, -1, 3, -16);
		helper.setBlock(Blocks.planks, -1, 3, 13);
		helper.setBlock(Blocks.planks, -1, 3, 8);
		helper.setBlock(Blocks.planks, -1, 4, -15);
		helper.setBlock(Blocks.planks, -1, 4, -16);
		helper.setBlock(Blocks.planks, -1, 4, -17);
		helper.setBlock(Blocks.planks, -1, 4, 13);
		helper.setBlock(Blocks.planks, -1, 4, 8);
		helper.setBlock(Blocks.planks, -1, 5, -17);
		helper.setBlock(Blocks.planks, -1, 5, 10);
		helper.setBlock(Blocks.planks, -1, 5, 4);
		helper.setBlock(Blocks.planks, -1, 5, 5);
		helper.setBlock(Blocks.planks, -1, 5, 6);
		helper.setBlock(Blocks.planks, -1, 5, 7);
		helper.setBlock(Blocks.planks, -1, 5, 8);
		helper.setBlock(Blocks.planks, -1, 5, 9);
		helper.setBlock(Blocks.planks, -1, 6, 10);
		helper.setBlock(Blocks.planks, -1, 6, 4);
		helper.setBlock(Blocks.planks, -1, 6, 5);
		helper.setBlock(Blocks.planks, -1, 6, 6);
		helper.setBlock(Blocks.planks, -1, 6, 7);
		helper.setBlock(Blocks.planks, -1, 6, 8);
		helper.setBlock(Blocks.planks, -1, 6, 9);
		helper.setBlock(Blocks.planks, -2, 2, -1);
		helper.setBlock(Blocks.planks, -2, 2, -10);
		helper.setBlock(Blocks.planks, -2, 2, -11);
		helper.setBlock(Blocks.planks, -2, 2, -12);
		helper.setBlock(Blocks.planks, -2, 2, -13);
		helper.setBlock(Blocks.planks, -2, 2, -14);
		helper.setBlock(Blocks.planks, -2, 2, -2);
		helper.setBlock(Blocks.planks, -2, 2, -3);
		helper.setBlock(Blocks.planks, -2, 2, -4);
		helper.setBlock(Blocks.planks, -2, 2, -5);
		helper.setBlock(Blocks.planks, -2, 2, -6);
		helper.setBlock(Blocks.planks, -2, 2, -7);
		helper.setBlock(Blocks.planks, -2, 2, -8);
		helper.setBlock(Blocks.planks, -2, 2, -9);
		helper.setBlock(Blocks.planks, -2, 2, 0);
		helper.setBlock(Blocks.planks, -2, 2, 1);
		helper.setBlock(Blocks.planks, -2, 2, 12);
		helper.setBlock(Blocks.planks, -2, 2, 13);
		helper.setBlock(Blocks.planks, -2, 2, 2);
		helper.setBlock(Blocks.planks, -2, 2, 3);
		helper.setBlock(Blocks.planks, -2, 2, 4);
		helper.setBlock(Blocks.planks, -2, 2, 5);
		helper.setBlock(Blocks.planks, -2, 2, 6);
		helper.setBlock(Blocks.planks, -2, 2, 7);
		helper.setBlock(Blocks.planks, -2, 2, 8);
		helper.setBlock(Blocks.planks, -2, 3, -1);
		helper.setBlock(Blocks.planks, -2, 3, -10);
		helper.setBlock(Blocks.planks, -2, 3, -11);
		helper.setBlock(Blocks.planks, -2, 3, -12);
		helper.setBlock(Blocks.planks, -2, 3, -13);
		helper.setBlock(Blocks.planks, -2, 3, -14);
		helper.setBlock(Blocks.planks, -2, 3, -15);
		helper.setBlock(Blocks.planks, -2, 3, -2);
		helper.setBlock(Blocks.planks, -2, 3, -3);
		helper.setBlock(Blocks.planks, -2, 3, -4);
		helper.setBlock(Blocks.planks, -2, 3, -5);
		helper.setBlock(Blocks.planks, -2, 3, -6);
		helper.setBlock(Blocks.planks, -2, 3, -7);
		helper.setBlock(Blocks.planks, -2, 3, -8);
		helper.setBlock(Blocks.planks, -2, 3, -9);
		helper.setBlock(Blocks.planks, -2, 3, 0);
		helper.setBlock(Blocks.planks, -2, 3, 1);
		helper.setBlock(Blocks.planks, -2, 3, 13);
		helper.setBlock(Blocks.planks, -2, 3, 2);
		helper.setBlock(Blocks.planks, -2, 3, 3);
		helper.setBlock(Blocks.planks, -2, 3, 4);
		helper.setBlock(Blocks.planks, -2, 3, 5);
		helper.setBlock(Blocks.planks, -2, 3, 6);
		helper.setBlock(Blocks.planks, -2, 3, 7);
		helper.setBlock(Blocks.planks, -2, 3, 8);
		helper.setBlock(Blocks.planks, -2, 4, -1);
		helper.setBlock(Blocks.planks, -2, 4, -10);
		helper.setBlock(Blocks.planks, -2, 4, -11);
		helper.setBlock(Blocks.planks, -2, 4, -12);
		helper.setBlock(Blocks.planks, -2, 4, -13);
		helper.setBlock(Blocks.planks, -2, 4, -14);
		helper.setBlock(Blocks.planks, -2, 4, -15);
		helper.setBlock(Blocks.planks, -2, 4, -2);
		helper.setBlock(Blocks.planks, -2, 4, -3);
		helper.setBlock(Blocks.planks, -2, 4, -4);
		helper.setBlock(Blocks.planks, -2, 4, -5);
		helper.setBlock(Blocks.planks, -2, 4, -6);
		helper.setBlock(Blocks.planks, -2, 4, -7);
		helper.setBlock(Blocks.planks, -2, 4, -8);
		helper.setBlock(Blocks.planks, -2, 4, -9);
		helper.setBlock(Blocks.planks, -2, 4, 0);
		helper.setBlock(Blocks.planks, -2, 4, 1);
		helper.setBlock(Blocks.planks, -2, 4, 13);
		helper.setBlock(Blocks.planks, -2, 4, 2);
		helper.setBlock(Blocks.planks, -2, 4, 3);
		helper.setBlock(Blocks.planks, -2, 4, 4);
		helper.setBlock(Blocks.planks, -2, 4, 5);
		helper.setBlock(Blocks.planks, -2, 4, 6);
		helper.setBlock(Blocks.planks, -2, 4, 7);
		helper.setBlock(Blocks.planks, -2, 4, 8);
		helper.setBlock(Blocks.planks, -3, 2, -1);
		helper.setBlock(Blocks.planks, -3, 2, -2);
		helper.setBlock(Blocks.planks, -3, 2, 0);
		helper.setBlock(Blocks.planks, -3, 2, 1);
		helper.setBlock(Blocks.planks, -3, 2, 12);
		helper.setBlock(Blocks.planks, -3, 2, 2);
		helper.setBlock(Blocks.planks, -3, 2, 3);
		helper.setBlock(Blocks.planks, -3, 2, 4);
		helper.setBlock(Blocks.planks, -3, 2, 5);
		helper.setBlock(Blocks.planks, -3, 2, 6);
		helper.setBlock(Blocks.planks, -3, 2, 7);
		helper.setBlock(Blocks.planks, -3, 2, 8);
		helper.setBlock(Blocks.planks, -3, 2, 9);
		helper.setBlock(Blocks.planks, -3, 3, -13);
		helper.setBlock(Blocks.planks, -3, 3, -14);
		helper.setBlock(Blocks.planks, -3, 3, 12);
		helper.setBlock(Blocks.planks, -3, 4, -13);
		helper.setBlock(Blocks.planks, -3, 4, -14);
		helper.setBlock(Blocks.planks, -3, 4, 12);
		helper.setBlock(Blocks.planks, -4, 1, -21);
		helper.setBlock(Blocks.planks, -4, 3, -1);
		helper.setBlock(Blocks.planks, -4, 3, -10);
		helper.setBlock(Blocks.planks, -4, 3, -11);
		helper.setBlock(Blocks.planks, -4, 3, -12);
		helper.setBlock(Blocks.planks, -4, 3, -13);
		helper.setBlock(Blocks.planks, -4, 3, -2);
		helper.setBlock(Blocks.planks, -4, 3, -3);
		helper.setBlock(Blocks.planks, -4, 3, -4);
		helper.setBlock(Blocks.planks, -4, 3, -5);
		helper.setBlock(Blocks.planks, -4, 3, -6);
		helper.setBlock(Blocks.planks, -4, 3, -7);
		helper.setBlock(Blocks.planks, -4, 3, -8);
		helper.setBlock(Blocks.planks, -4, 3, -9);
		helper.setBlock(Blocks.planks, -4, 3, 0);
		helper.setBlock(Blocks.planks, -4, 3, 1);
		helper.setBlock(Blocks.planks, -4, 3, 10);
		helper.setBlock(Blocks.planks, -4, 3, 11);
		helper.setBlock(Blocks.planks, -4, 3, 12);
		helper.setBlock(Blocks.planks, -4, 3, 2);
		helper.setBlock(Blocks.planks, -4, 3, 3);
		helper.setBlock(Blocks.planks, -4, 3, 4);
		helper.setBlock(Blocks.planks, -4, 3, 5);
		helper.setBlock(Blocks.planks, -4, 3, 6);
		helper.setBlock(Blocks.planks, -4, 3, 7);
		helper.setBlock(Blocks.planks, -4, 3, 8);
		helper.setBlock(Blocks.planks, -4, 3, 9);
		helper.setBlock(Blocks.planks, -4, 4, -1);
		helper.setBlock(Blocks.planks, -4, 4, -10);
		helper.setBlock(Blocks.planks, -4, 4, -11);
		helper.setBlock(Blocks.planks, -4, 4, -12);
		helper.setBlock(Blocks.planks, -4, 4, -13);
		helper.setBlock(Blocks.planks, -4, 4, -2);
		helper.setBlock(Blocks.planks, -4, 4, -3);
		helper.setBlock(Blocks.planks, -4, 4, -4);
		helper.setBlock(Blocks.planks, -4, 4, -5);
		helper.setBlock(Blocks.planks, -4, 4, -6);
		helper.setBlock(Blocks.planks, -4, 4, -7);
		helper.setBlock(Blocks.planks, -4, 4, -8);
		helper.setBlock(Blocks.planks, -4, 4, -9);
		helper.setBlock(Blocks.planks, -4, 4, 0);
		helper.setBlock(Blocks.planks, -4, 4, 1);
		helper.setBlock(Blocks.planks, -4, 4, 10);
		helper.setBlock(Blocks.planks, -4, 4, 11);
		helper.setBlock(Blocks.planks, -4, 4, 12);
		helper.setBlock(Blocks.planks, -4, 4, 2);
		helper.setBlock(Blocks.planks, -4, 4, 3);
		helper.setBlock(Blocks.planks, -4, 4, 4);
		helper.setBlock(Blocks.planks, -4, 4, 5);
		helper.setBlock(Blocks.planks, -4, 4, 6);
		helper.setBlock(Blocks.planks, -4, 4, 7);
		helper.setBlock(Blocks.planks, -4, 4, 8);
		helper.setBlock(Blocks.planks, -4, 4, 9);
		helper.setBlock(Blocks.planks, 0, 1, -1);
		helper.setBlock(Blocks.planks, 0, 1, -10);
		helper.setBlock(Blocks.planks, 0, 1, -11);
		helper.setBlock(Blocks.planks, 0, 1, -12);
		helper.setBlock(Blocks.planks, 0, 1, -13);
		helper.setBlock(Blocks.planks, 0, 1, -2);
		helper.setBlock(Blocks.planks, 0, 1, -3);
		helper.setBlock(Blocks.planks, 0, 1, -4);
		helper.setBlock(Blocks.planks, 0, 1, -5);
		helper.setBlock(Blocks.planks, 0, 1, -6);
		helper.setBlock(Blocks.planks, 0, 1, -7);
		helper.setBlock(Blocks.planks, 0, 1, -8);
		helper.setBlock(Blocks.planks, 0, 1, -9);
		helper.setBlock(Blocks.planks, 0, 1, 0);
		helper.setBlock(Blocks.planks, 0, 1, 1);
		helper.setBlock(Blocks.planks, 0, 1, 10);
		helper.setBlock(Blocks.planks, 0, 1, 11);
		helper.setBlock(Blocks.planks, 0, 1, 2);
		helper.setBlock(Blocks.planks, 0, 1, 3);
		helper.setBlock(Blocks.planks, 0, 1, 4);
		helper.setBlock(Blocks.planks, 0, 1, 5);
		helper.setBlock(Blocks.planks, 0, 1, 6);
		helper.setBlock(Blocks.planks, 0, 1, 7);
		helper.setBlock(Blocks.planks, 0, 1, 8);
		helper.setBlock(Blocks.planks, 0, 1, 9);
		helper.setBlock(Blocks.planks, 0, 2, -14);
		helper.setBlock(Blocks.planks, 0, 2, -15);
		helper.setBlock(Blocks.planks, 0, 2, 13);
		helper.setBlock(Blocks.planks, 0, 2, 8);
		helper.setBlock(Blocks.planks, 0, 3, -16);
		helper.setBlock(Blocks.planks, 0, 3, -17);
		helper.setBlock(Blocks.planks, 0, 3, 13);
		helper.setBlock(Blocks.planks, 0, 3, 8);
		helper.setBlock(Blocks.planks, 0, 4, -16);
		helper.setBlock(Blocks.planks, 0, 4, -17);
		helper.setBlock(Blocks.planks, 0, 4, -18);
		helper.setBlock(Blocks.planks, 0, 4, 13);
		helper.setBlock(Blocks.planks, 0, 4, 8);
		helper.setBlock(Blocks.planks, 0, 5, -18);
		helper.setBlock(Blocks.planks, 0, 5, 10);
		helper.setBlock(Blocks.planks, 0, 5, 4);
		helper.setBlock(Blocks.planks, 0, 6, 10);
		helper.setBlock(Blocks.planks, 0, 6, 4);
		helper.setBlock(Blocks.planks, 1, 1, -1);
		helper.setBlock(Blocks.planks, 1, 1, -10);
		helper.setBlock(Blocks.planks, 1, 1, -11);
		helper.setBlock(Blocks.planks, 1, 1, -12);
		helper.setBlock(Blocks.planks, 1, 1, -13);
		helper.setBlock(Blocks.planks, 1, 1, -2);
		helper.setBlock(Blocks.planks, 1, 1, -3);
		helper.setBlock(Blocks.planks, 1, 1, -4);
		helper.setBlock(Blocks.planks, 1, 1, -5);
		helper.setBlock(Blocks.planks, 1, 1, -6);
		helper.setBlock(Blocks.planks, 1, 1, -7);
		helper.setBlock(Blocks.planks, 1, 1, -8);
		helper.setBlock(Blocks.planks, 1, 1, -9);
		helper.setBlock(Blocks.planks, 1, 1, 0);
		helper.setBlock(Blocks.planks, 1, 1, 1);
		helper.setBlock(Blocks.planks, 1, 1, 10);
		helper.setBlock(Blocks.planks, 1, 1, 11);
		helper.setBlock(Blocks.planks, 1, 1, 12);
		helper.setBlock(Blocks.planks, 1, 1, 2);
		helper.setBlock(Blocks.planks, 1, 1, 3);
		helper.setBlock(Blocks.planks, 1, 1, 4);
		helper.setBlock(Blocks.planks, 1, 1, 5);
		helper.setBlock(Blocks.planks, 1, 1, 6);
		helper.setBlock(Blocks.planks, 1, 1, 7);
		helper.setBlock(Blocks.planks, 1, 1, 8);
		helper.setBlock(Blocks.planks, 1, 1, 9);
		helper.setBlock(Blocks.planks, 1, 2, -15);
		helper.setBlock(Blocks.planks, 1, 2, -16);
		helper.setBlock(Blocks.planks, 1, 2, 10);
		helper.setBlock(Blocks.planks, 1, 2, 13);
		helper.setBlock(Blocks.planks, 1, 2, 9);
		helper.setBlock(Blocks.planks, 1, 3, -17);
		helper.setBlock(Blocks.planks, 1, 3, -18);
		helper.setBlock(Blocks.planks, 1, 3, 13);
		helper.setBlock(Blocks.planks, 1, 3, 9);
		helper.setBlock(Blocks.planks, 1, 4, -18);
		helper.setBlock(Blocks.planks, 1, 4, 13);
		helper.setBlock(Blocks.planks, 1, 4, 8);
		helper.setBlock(Blocks.planks, 1, 5, -18);
		helper.setBlock(Blocks.planks, 1, 5, -19);
		helper.setBlock(Blocks.planks, 1, 5, 10);
		helper.setBlock(Blocks.planks, 1, 5, 4);
		helper.setBlock(Blocks.planks, 1, 6, 10);
		helper.setBlock(Blocks.planks, 1, 6, 4);
		helper.setBlock(Blocks.planks, 2, 1, -1);
		helper.setBlock(Blocks.planks, 2, 1, -10);
		helper.setBlock(Blocks.planks, 2, 1, -11);
		helper.setBlock(Blocks.planks, 2, 1, -12);
		helper.setBlock(Blocks.planks, 2, 1, -13);
		helper.setBlock(Blocks.planks, 2, 1, -14);
		helper.setBlock(Blocks.planks, 2, 1, -2);
		helper.setBlock(Blocks.planks, 2, 1, -3);
		helper.setBlock(Blocks.planks, 2, 1, -4);
		helper.setBlock(Blocks.planks, 2, 1, -5);
		helper.setBlock(Blocks.planks, 2, 1, -6);
		helper.setBlock(Blocks.planks, 2, 1, -7);
		helper.setBlock(Blocks.planks, 2, 1, -8);
		helper.setBlock(Blocks.planks, 2, 1, -9);
		helper.setBlock(Blocks.planks, 2, 1, 0);
		helper.setBlock(Blocks.planks, 2, 1, 1);
		helper.setBlock(Blocks.planks, 2, 1, 10);
		helper.setBlock(Blocks.planks, 2, 1, 11);
		helper.setBlock(Blocks.planks, 2, 1, 12);
		helper.setBlock(Blocks.planks, 2, 1, 2);
		helper.setBlock(Blocks.planks, 2, 1, 3);
		helper.setBlock(Blocks.planks, 2, 1, 4);
		helper.setBlock(Blocks.planks, 2, 1, 5);
		helper.setBlock(Blocks.planks, 2, 1, 6);
		helper.setBlock(Blocks.planks, 2, 1, 7);
		helper.setBlock(Blocks.planks, 2, 1, 8);
		helper.setBlock(Blocks.planks, 2, 1, 9);
		helper.setBlock(Blocks.planks, 2, 2, -16);
		helper.setBlock(Blocks.planks, 2, 2, 13);
		helper.setBlock(Blocks.planks, 2, 3, -17);
		helper.setBlock(Blocks.planks, 2, 3, -18);
		helper.setBlock(Blocks.planks, 2, 3, 13);
		helper.setBlock(Blocks.planks, 2, 4, -18);
		helper.setBlock(Blocks.planks, 2, 4, -19);
		helper.setBlock(Blocks.planks, 2, 4, 13);
		helper.setBlock(Blocks.planks, 2, 4, 8);
		helper.setBlock(Blocks.planks, 2, 4, 9);
		helper.setBlock(Blocks.planks, 2, 5, -19);
		helper.setBlock(Blocks.planks, 2, 5, -20);
		helper.setBlock(Blocks.planks, 2, 5, 10);
		helper.setBlock(Blocks.planks, 2, 6, 10);
		helper.setBlock(Blocks.planks, 2, 7, 4);
		helper.setBlock(Blocks.planks, 3, 1, -1);
		helper.setBlock(Blocks.planks, 3, 1, -10);
		helper.setBlock(Blocks.planks, 3, 1, -11);
		helper.setBlock(Blocks.planks, 3, 1, -12);
		helper.setBlock(Blocks.planks, 3, 1, -13);
		helper.setBlock(Blocks.planks, 3, 1, -2);
		helper.setBlock(Blocks.planks, 3, 1, -3);
		helper.setBlock(Blocks.planks, 3, 1, -4);
		helper.setBlock(Blocks.planks, 3, 1, -5);
		helper.setBlock(Blocks.planks, 3, 1, -6);
		helper.setBlock(Blocks.planks, 3, 1, -7);
		helper.setBlock(Blocks.planks, 3, 1, -8);
		helper.setBlock(Blocks.planks, 3, 1, -9);
		helper.setBlock(Blocks.planks, 3, 1, 0);
		helper.setBlock(Blocks.planks, 3, 1, 1);
		helper.setBlock(Blocks.planks, 3, 1, 10);
		helper.setBlock(Blocks.planks, 3, 1, 11);
		helper.setBlock(Blocks.planks, 3, 1, 12);
		helper.setBlock(Blocks.planks, 3, 1, 2);
		helper.setBlock(Blocks.planks, 3, 1, 3);
		helper.setBlock(Blocks.planks, 3, 1, 4);
		helper.setBlock(Blocks.planks, 3, 1, 5);
		helper.setBlock(Blocks.planks, 3, 1, 6);
		helper.setBlock(Blocks.planks, 3, 1, 7);
		helper.setBlock(Blocks.planks, 3, 1, 8);
		helper.setBlock(Blocks.planks, 3, 1, 9);
		helper.setBlock(Blocks.planks, 3, 2, -15);
		helper.setBlock(Blocks.planks, 3, 2, -16);
		helper.setBlock(Blocks.planks, 3, 2, 10);
		helper.setBlock(Blocks.planks, 3, 2, 13);
		helper.setBlock(Blocks.planks, 3, 2, 9);
		helper.setBlock(Blocks.planks, 3, 3, -17);
		helper.setBlock(Blocks.planks, 3, 3, -18);
		helper.setBlock(Blocks.planks, 3, 3, 10);
		helper.setBlock(Blocks.planks, 3, 3, 13);
		helper.setBlock(Blocks.planks, 3, 3, 9);
		helper.setBlock(Blocks.planks, 3, 4, -18);
		helper.setBlock(Blocks.planks, 3, 4, 13);
		helper.setBlock(Blocks.planks, 3, 4, 8);
		helper.setBlock(Blocks.planks, 3, 4, 9);
		helper.setBlock(Blocks.planks, 3, 5, -18);
		helper.setBlock(Blocks.planks, 3, 5, -19);
		helper.setBlock(Blocks.planks, 3, 5, 10);
		helper.setBlock(Blocks.planks, 3, 5, 4);
		helper.setBlock(Blocks.planks, 3, 6, 10);
		helper.setBlock(Blocks.planks, 3, 6, 4);
		helper.setBlock(Blocks.planks, 4, 1, -1);
		helper.setBlock(Blocks.planks, 4, 1, -10);
		helper.setBlock(Blocks.planks, 4, 1, -11);
		helper.setBlock(Blocks.planks, 4, 1, -12);
		helper.setBlock(Blocks.planks, 4, 1, -13);
		helper.setBlock(Blocks.planks, 4, 1, -2);
		helper.setBlock(Blocks.planks, 4, 1, -3);
		helper.setBlock(Blocks.planks, 4, 1, -4);
		helper.setBlock(Blocks.planks, 4, 1, -5);
		helper.setBlock(Blocks.planks, 4, 1, -6);
		helper.setBlock(Blocks.planks, 4, 1, -7);
		helper.setBlock(Blocks.planks, 4, 1, -8);
		helper.setBlock(Blocks.planks, 4, 1, -9);
		helper.setBlock(Blocks.planks, 4, 1, 0);
		helper.setBlock(Blocks.planks, 4, 1, 1);
		helper.setBlock(Blocks.planks, 4, 1, 10);
		helper.setBlock(Blocks.planks, 4, 1, 11);
		helper.setBlock(Blocks.planks, 4, 1, 2);
		helper.setBlock(Blocks.planks, 4, 1, 3);
		helper.setBlock(Blocks.planks, 4, 1, 4);
		helper.setBlock(Blocks.planks, 4, 1, 5);
		helper.setBlock(Blocks.planks, 4, 1, 6);
		helper.setBlock(Blocks.planks, 4, 1, 7);
		helper.setBlock(Blocks.planks, 4, 1, 8);
		helper.setBlock(Blocks.planks, 4, 1, 9);
		helper.setBlock(Blocks.planks, 4, 2, -14);
		helper.setBlock(Blocks.planks, 4, 2, -15);
		helper.setBlock(Blocks.planks, 4, 2, 13);
		helper.setBlock(Blocks.planks, 4, 2, 8);
		helper.setBlock(Blocks.planks, 4, 3, -16);
		helper.setBlock(Blocks.planks, 4, 3, -17);
		helper.setBlock(Blocks.planks, 4, 3, 13);
		helper.setBlock(Blocks.planks, 4, 3, 8);
		helper.setBlock(Blocks.planks, 4, 4, -16);
		helper.setBlock(Blocks.planks, 4, 4, -17);
		helper.setBlock(Blocks.planks, 4, 4, -18);
		helper.setBlock(Blocks.planks, 4, 4, 13);
		helper.setBlock(Blocks.planks, 4, 4, 8);
		helper.setBlock(Blocks.planks, 4, 5, -18);
		helper.setBlock(Blocks.planks, 4, 5, 10);
		helper.setBlock(Blocks.planks, 4, 5, 4);
		helper.setBlock(Blocks.planks, 4, 6, 10);
		helper.setBlock(Blocks.planks, 4, 6, 4);
		helper.setBlock(Blocks.planks, 5, 2, -1);
		helper.setBlock(Blocks.planks, 5, 2, -10);
		helper.setBlock(Blocks.planks, 5, 2, -11);
		helper.setBlock(Blocks.planks, 5, 2, -12);
		helper.setBlock(Blocks.planks, 5, 2, -13);
		helper.setBlock(Blocks.planks, 5, 2, -14);
		helper.setBlock(Blocks.planks, 5, 2, -2);
		helper.setBlock(Blocks.planks, 5, 2, -3);
		helper.setBlock(Blocks.planks, 5, 2, -4);
		helper.setBlock(Blocks.planks, 5, 2, -5);
		helper.setBlock(Blocks.planks, 5, 2, -6);
		helper.setBlock(Blocks.planks, 5, 2, -7);
		helper.setBlock(Blocks.planks, 5, 2, -8);
		helper.setBlock(Blocks.planks, 5, 2, -9);
		helper.setBlock(Blocks.planks, 5, 2, 0);
		helper.setBlock(Blocks.planks, 5, 2, 1);
		helper.setBlock(Blocks.planks, 5, 2, 13);
		helper.setBlock(Blocks.planks, 5, 2, 2);
		helper.setBlock(Blocks.planks, 5, 2, 3);
		helper.setBlock(Blocks.planks, 5, 2, 4);
		helper.setBlock(Blocks.planks, 5, 2, 5);
		helper.setBlock(Blocks.planks, 5, 2, 6);
		helper.setBlock(Blocks.planks, 5, 2, 7);
		helper.setBlock(Blocks.planks, 5, 2, 8);
		helper.setBlock(Blocks.planks, 5, 3, -15);
		helper.setBlock(Blocks.planks, 5, 3, -16);
		helper.setBlock(Blocks.planks, 5, 3, 13);
		helper.setBlock(Blocks.planks, 5, 3, 8);
		helper.setBlock(Blocks.planks, 5, 4, -15);
		helper.setBlock(Blocks.planks, 5, 4, -16);
		helper.setBlock(Blocks.planks, 5, 4, -17);
		helper.setBlock(Blocks.planks, 5, 4, 13);
		helper.setBlock(Blocks.planks, 5, 4, 8);
		helper.setBlock(Blocks.planks, 5, 5, -17);
		helper.setBlock(Blocks.planks, 5, 5, 10);
		helper.setBlock(Blocks.planks, 5, 5, 4);
		helper.setBlock(Blocks.planks, 5, 5, 5);
		helper.setBlock(Blocks.planks, 5, 5, 6);
		helper.setBlock(Blocks.planks, 5, 5, 7);
		helper.setBlock(Blocks.planks, 5, 5, 8);
		helper.setBlock(Blocks.planks, 5, 5, 9);
		helper.setBlock(Blocks.planks, 5, 6, 10);
		helper.setBlock(Blocks.planks, 5, 6, 4);
		helper.setBlock(Blocks.planks, 5, 6, 5);
		helper.setBlock(Blocks.planks, 5, 6, 6);
		helper.setBlock(Blocks.planks, 5, 6, 7);
		helper.setBlock(Blocks.planks, 5, 6, 8);
		helper.setBlock(Blocks.planks, 5, 6, 9);
		helper.setBlock(Blocks.planks, 6, 2, -1);
		helper.setBlock(Blocks.planks, 6, 2, -10);
		helper.setBlock(Blocks.planks, 6, 2, -11);
		helper.setBlock(Blocks.planks, 6, 2, -12);
		helper.setBlock(Blocks.planks, 6, 2, -13);
		helper.setBlock(Blocks.planks, 6, 2, -2);
		helper.setBlock(Blocks.planks, 6, 2, -3);
		helper.setBlock(Blocks.planks, 6, 2, -4);
		helper.setBlock(Blocks.planks, 6, 2, -5);
		helper.setBlock(Blocks.planks, 6, 2, -6);
		helper.setBlock(Blocks.planks, 6, 2, -7);
		helper.setBlock(Blocks.planks, 6, 2, -8);
		helper.setBlock(Blocks.planks, 6, 2, -9);
		helper.setBlock(Blocks.planks, 6, 2, 0);
		helper.setBlock(Blocks.planks, 6, 2, 1);
		helper.setBlock(Blocks.planks, 6, 2, 12);
		helper.setBlock(Blocks.planks, 6, 2, 13);
		helper.setBlock(Blocks.planks, 6, 2, 2);
		helper.setBlock(Blocks.planks, 6, 2, 3);
		helper.setBlock(Blocks.planks, 6, 2, 4);
		helper.setBlock(Blocks.planks, 6, 2, 5);
		helper.setBlock(Blocks.planks, 6, 2, 6);
		helper.setBlock(Blocks.planks, 6, 2, 7);
		helper.setBlock(Blocks.planks, 6, 2, 8);
		helper.setBlock(Blocks.planks, 6, 3, -1);
		helper.setBlock(Blocks.planks, 6, 3, -10);
		helper.setBlock(Blocks.planks, 6, 3, -11);
		helper.setBlock(Blocks.planks, 6, 3, -12);
		helper.setBlock(Blocks.planks, 6, 3, -13);
		helper.setBlock(Blocks.planks, 6, 3, -14);
		helper.setBlock(Blocks.planks, 6, 3, -15);
		helper.setBlock(Blocks.planks, 6, 3, -2);
		helper.setBlock(Blocks.planks, 6, 3, -3);
		helper.setBlock(Blocks.planks, 6, 3, -4);
		helper.setBlock(Blocks.planks, 6, 3, -5);
		helper.setBlock(Blocks.planks, 6, 3, -6);
		helper.setBlock(Blocks.planks, 6, 3, -7);
		helper.setBlock(Blocks.planks, 6, 3, -8);
		helper.setBlock(Blocks.planks, 6, 3, -9);
		helper.setBlock(Blocks.planks, 6, 3, 0);
		helper.setBlock(Blocks.planks, 6, 3, 1);
		helper.setBlock(Blocks.planks, 6, 3, 13);
		helper.setBlock(Blocks.planks, 6, 3, 2);
		helper.setBlock(Blocks.planks, 6, 3, 3);
		helper.setBlock(Blocks.planks, 6, 3, 4);
		helper.setBlock(Blocks.planks, 6, 3, 5);
		helper.setBlock(Blocks.planks, 6, 3, 6);
		helper.setBlock(Blocks.planks, 6, 3, 7);
		helper.setBlock(Blocks.planks, 6, 3, 8);
		helper.setBlock(Blocks.planks, 6, 4, -1);
		helper.setBlock(Blocks.planks, 6, 4, -10);
		helper.setBlock(Blocks.planks, 6, 4, -11);
		helper.setBlock(Blocks.planks, 6, 4, -12);
		helper.setBlock(Blocks.planks, 6, 4, -13);
		helper.setBlock(Blocks.planks, 6, 4, -14);
		helper.setBlock(Blocks.planks, 6, 4, -15);
		helper.setBlock(Blocks.planks, 6, 4, -2);
		helper.setBlock(Blocks.planks, 6, 4, -3);
		helper.setBlock(Blocks.planks, 6, 4, -4);
		helper.setBlock(Blocks.planks, 6, 4, -5);
		helper.setBlock(Blocks.planks, 6, 4, -6);
		helper.setBlock(Blocks.planks, 6, 4, -7);
		helper.setBlock(Blocks.planks, 6, 4, -8);
		helper.setBlock(Blocks.planks, 6, 4, -9);
		helper.setBlock(Blocks.planks, 6, 4, 0);
		helper.setBlock(Blocks.planks, 6, 4, 1);
		helper.setBlock(Blocks.planks, 6, 4, 13);
		helper.setBlock(Blocks.planks, 6, 4, 2);
		helper.setBlock(Blocks.planks, 6, 4, 3);
		helper.setBlock(Blocks.planks, 6, 4, 4);
		helper.setBlock(Blocks.planks, 6, 4, 5);
		helper.setBlock(Blocks.planks, 6, 4, 6);
		helper.setBlock(Blocks.planks, 6, 4, 7);
		helper.setBlock(Blocks.planks, 6, 4, 8);
		helper.setBlock(Blocks.planks, 7, 2, 12);
		helper.setBlock(Blocks.planks, 7, 2, 8);
		helper.setBlock(Blocks.planks, 7, 2, 9);
		helper.setBlock(Blocks.planks, 7, 3, -13);
		helper.setBlock(Blocks.planks, 7, 3, -14);
		helper.setBlock(Blocks.planks, 7, 3, 12);
		helper.setBlock(Blocks.planks, 7, 4, -13);
		helper.setBlock(Blocks.planks, 7, 4, -14);
		helper.setBlock(Blocks.planks, 7, 4, 12);
		helper.setBlock(Blocks.planks, 8, 3, -1);
		helper.setBlock(Blocks.planks, 8, 3, -10);
		helper.setBlock(Blocks.planks, 8, 3, -11);
		helper.setBlock(Blocks.planks, 8, 3, -12);
		helper.setBlock(Blocks.planks, 8, 3, -13);
		helper.setBlock(Blocks.planks, 8, 3, -2);
		helper.setBlock(Blocks.planks, 8, 3, -3);
		helper.setBlock(Blocks.planks, 8, 3, -4);
		helper.setBlock(Blocks.planks, 8, 3, -5);
		helper.setBlock(Blocks.planks, 8, 3, -6);
		helper.setBlock(Blocks.planks, 8, 3, -7);
		helper.setBlock(Blocks.planks, 8, 3, -8);
		helper.setBlock(Blocks.planks, 8, 3, -9);
		helper.setBlock(Blocks.planks, 8, 3, 0);
		helper.setBlock(Blocks.planks, 8, 3, 1);
		helper.setBlock(Blocks.planks, 8, 3, 10);
		helper.setBlock(Blocks.planks, 8, 3, 11);
		helper.setBlock(Blocks.planks, 8, 3, 12);
		helper.setBlock(Blocks.planks, 8, 3, 2);
		helper.setBlock(Blocks.planks, 8, 3, 3);
		helper.setBlock(Blocks.planks, 8, 3, 4);
		helper.setBlock(Blocks.planks, 8, 3, 5);
		helper.setBlock(Blocks.planks, 8, 3, 6);
		helper.setBlock(Blocks.planks, 8, 3, 7);
		helper.setBlock(Blocks.planks, 8, 3, 8);
		helper.setBlock(Blocks.planks, 8, 3, 9);
		helper.setBlock(Blocks.planks, 8, 4, -1);
		helper.setBlock(Blocks.planks, 8, 4, -10);
		helper.setBlock(Blocks.planks, 8, 4, -11);
		helper.setBlock(Blocks.planks, 8, 4, -12);
		helper.setBlock(Blocks.planks, 8, 4, -13);
		helper.setBlock(Blocks.planks, 8, 4, -2);
		helper.setBlock(Blocks.planks, 8, 4, -3);
		helper.setBlock(Blocks.planks, 8, 4, -4);
		helper.setBlock(Blocks.planks, 8, 4, -5);
		helper.setBlock(Blocks.planks, 8, 4, -6);
		helper.setBlock(Blocks.planks, 8, 4, -7);
		helper.setBlock(Blocks.planks, 8, 4, -8);
		helper.setBlock(Blocks.planks, 8, 4, -9);
		helper.setBlock(Blocks.planks, 8, 4, 0);
		helper.setBlock(Blocks.planks, 8, 4, 1);
		helper.setBlock(Blocks.planks, 8, 4, 10);
		helper.setBlock(Blocks.planks, 8, 4, 11);
		helper.setBlock(Blocks.planks, 8, 4, 12);
		helper.setBlock(Blocks.planks, 8, 4, 2);
		helper.setBlock(Blocks.planks, 8, 4, 3);
		helper.setBlock(Blocks.planks, 8, 4, 4);
		helper.setBlock(Blocks.planks, 8, 4, 5);
		helper.setBlock(Blocks.planks, 8, 4, 6);
		helper.setBlock(Blocks.planks, 8, 4, 7);
		helper.setBlock(Blocks.planks, 8, 4, 8);
		helper.setBlock(Blocks.planks, 8, 4, 9);
		helper.setBlock(Blocks.tnt, -3, 3, -10);
		helper.setBlock(Blocks.tnt, -3, 3, -11);
		helper.setBlock(Blocks.tnt, -3, 3, -12);
		helper.setBlock(Blocks.tnt, -3, 3, -3);
		helper.setBlock(Blocks.tnt, -3, 3, -4);
		helper.setBlock(Blocks.tnt, -3, 3, -5);
		helper.setBlock(Blocks.tnt, -3, 3, -6);
		helper.setBlock(Blocks.tnt, -3, 3, -7);
		helper.setBlock(Blocks.tnt, -3, 3, -8);
		helper.setBlock(Blocks.tnt, -3, 3, -9);
		helper.setBlock(Blocks.tnt, 2, 22, -5);
		helper.setBlock(Blocks.tnt, 7, 3, -10);
		helper.setBlock(Blocks.tnt, 7, 3, -11);
		helper.setBlock(Blocks.tnt, 7, 3, -12);
		helper.setBlock(Blocks.tnt, 7, 3, -3);
		helper.setBlock(Blocks.tnt, 7, 3, -4);
		helper.setBlock(Blocks.tnt, 7, 3, -5);
		helper.setBlock(Blocks.tnt, 7, 3, -6);
		helper.setBlock(Blocks.tnt, 7, 3, -7);
		helper.setBlock(Blocks.tnt, 7, 3, -8);
		helper.setBlock(Blocks.tnt, 7, 3, -9);
		helper.setBlock(Blocks.trapped_chest, 2, 23, -5, 3);
		helper.setBlock(Blocks.wool, -1, 10, -10, 15);
		helper.setBlock(Blocks.wool, -1, 10, -2, 0);
		helper.setBlock(Blocks.wool, -1, 11, -10, 15);
		helper.setBlock(Blocks.wool, -1, 11, -2, 15);
		helper.setBlock(Blocks.wool, -1, 12, -10, 15);
		helper.setBlock(Blocks.wool, -1, 12, -2, 0);
		helper.setBlock(Blocks.wool, -1, 13, -10, 15);
		helper.setBlock(Blocks.wool, -1, 13, -2, 0);
		helper.setBlock(Blocks.wool, -1, 14, -10, 15);
		helper.setBlock(Blocks.wool, -1, 14, -2, 15);
		helper.setBlock(Blocks.wool, -1, 15, -10, 15);
		helper.setBlock(Blocks.wool, -1, 15, -2, 0);
		helper.setBlock(Blocks.wool, -1, 16, -10, 0);
		helper.setBlock(Blocks.wool, -1, 16, -2, 0);
		helper.setBlock(Blocks.wool, -1, 17, -10, 15);
		helper.setBlock(Blocks.wool, -1, 17, -2, 0);
		helper.setBlock(Blocks.wool, -1, 8, -10, 15);
		helper.setBlock(Blocks.wool, -1, 8, -2, 15);
		helper.setBlock(Blocks.wool, -1, 9, -10, 0);
		helper.setBlock(Blocks.wool, -1, 9, -2, 0);
		helper.setBlock(Blocks.wool, 0, 10, -1, 15);
		helper.setBlock(Blocks.wool, 0, 10, -11, 15);
		helper.setBlock(Blocks.wool, 0, 11, -1, 15);
		helper.setBlock(Blocks.wool, 0, 11, -11, 15);
		helper.setBlock(Blocks.wool, 0, 12, -1, 0);
		helper.setBlock(Blocks.wool, 0, 12, -11, 15);
		helper.setBlock(Blocks.wool, 0, 13, -1, 0);
		helper.setBlock(Blocks.wool, 0, 13, -11, 0);
		helper.setBlock(Blocks.wool, 0, 14, -1, 15);
		helper.setBlock(Blocks.wool, 0, 14, -11, 15);
		helper.setBlock(Blocks.wool, 0, 15, -1, 15);
		helper.setBlock(Blocks.wool, 0, 15, -11, 0);
		helper.setBlock(Blocks.wool, 0, 16, -11, 15);
		helper.setBlock(Blocks.wool, 0, 17, -10, 15);
		helper.setBlock(Blocks.wool, 0, 17, -2, 15);
		helper.setBlock(Blocks.wool, 0, 9, -11, 0);
		helper.setBlock(Blocks.wool, 1, 10, -1, 0);
		helper.setBlock(Blocks.wool, 1, 10, -11, 15);
		helper.setBlock(Blocks.wool, 1, 10, -12, 0);
		helper.setBlock(Blocks.wool, 1, 10, 0, 15);
		helper.setBlock(Blocks.wool, 1, 11, -12, 0);
		helper.setBlock(Blocks.wool, 1, 11, 0, 15);
		helper.setBlock(Blocks.wool, 1, 12, -12, 0);
		helper.setBlock(Blocks.wool, 1, 12, 0, 0);
		helper.setBlock(Blocks.wool, 1, 13, -12, 0);
		helper.setBlock(Blocks.wool, 1, 13, 0, 15);
		helper.setBlock(Blocks.wool, 1, 14, -12, 15);
		helper.setBlock(Blocks.wool, 1, 14, 0, 0);
		helper.setBlock(Blocks.wool, 1, 15, -1, 0);
		helper.setBlock(Blocks.wool, 1, 15, -11, 0);
		helper.setBlock(Blocks.wool, 1, 15, -12, 15);
		helper.setBlock(Blocks.wool, 1, 15, 0, 0);
		helper.setBlock(Blocks.wool, 1, 16, -1, 0);
		helper.setBlock(Blocks.wool, 1, 16, -11, 0);
		helper.setBlock(Blocks.wool, 1, 17, -10, 0);
		helper.setBlock(Blocks.wool, 1, 17, -11, 0);
		helper.setBlock(Blocks.wool, 1, 17, -2, 0);
		helper.setBlock(Blocks.wool, 1, 8, -10, 15);
		helper.setBlock(Blocks.wool, 1, 8, -11, 15);
		helper.setBlock(Blocks.wool, 1, 8, -2, 15);
		helper.setBlock(Blocks.wool, 1, 9, -1, 15);
		helper.setBlock(Blocks.wool, 1, 9, -11, 0);
		helper.setBlock(Blocks.wool, 2, 10, -12, 0);
		helper.setBlock(Blocks.wool, 2, 10, 0, 0);
		helper.setBlock(Blocks.wool, 2, 11, -12, 0);
		helper.setBlock(Blocks.wool, 2, 11, 0, 0);
		helper.setBlock(Blocks.wool, 2, 12, -12, 15);
		helper.setBlock(Blocks.wool, 2, 12, 0, 0);
		helper.setBlock(Blocks.wool, 2, 13, -12, 15);
		helper.setBlock(Blocks.wool, 2, 13, 0, 15);
		helper.setBlock(Blocks.wool, 2, 14, -12, 15);
		helper.setBlock(Blocks.wool, 2, 14, 0, 15);
		helper.setBlock(Blocks.wool, 2, 15, -12, 15);
		helper.setBlock(Blocks.wool, 2, 15, 0, 15);
		helper.setBlock(Blocks.wool, 2, 16, -1, 15);
		helper.setBlock(Blocks.wool, 2, 16, -11, 0);
		helper.setBlock(Blocks.wool, 2, 16, -12, 0);
		helper.setBlock(Blocks.wool, 2, 16, 0, 0);
		helper.setBlock(Blocks.wool, 2, 17, -10, 0);
		helper.setBlock(Blocks.wool, 2, 17, -11, 15);
		helper.setBlock(Blocks.wool, 2, 17, -2, 0);
		helper.setBlock(Blocks.wool, 2, 8, -10, 15);
		helper.setBlock(Blocks.wool, 2, 8, -11, 0);
		helper.setBlock(Blocks.wool, 2, 8, -2, 15);
		helper.setBlock(Blocks.wool, 2, 9, -1, 0);
		helper.setBlock(Blocks.wool, 2, 9, -11, 15);
		helper.setBlock(Blocks.wool, 2, 9, -12, 0);
		helper.setBlock(Blocks.wool, 2, 9, 0, 15);
		helper.setBlock(Blocks.wool, 3, 10, -1, 0);
		helper.setBlock(Blocks.wool, 3, 10, -11, 15);
		helper.setBlock(Blocks.wool, 3, 10, -12, 0);
		helper.setBlock(Blocks.wool, 3, 10, 0, 0);
		helper.setBlock(Blocks.wool, 3, 11, -12, 0);
		helper.setBlock(Blocks.wool, 3, 11, 0, 15);
		helper.setBlock(Blocks.wool, 3, 12, -12, 0);
		helper.setBlock(Blocks.wool, 3, 12, 0, 15);
		helper.setBlock(Blocks.wool, 3, 13, -12, 15);
		helper.setBlock(Blocks.wool, 3, 13, 0, 0);
		helper.setBlock(Blocks.wool, 3, 14, -12, 0);
		helper.setBlock(Blocks.wool, 3, 14, 0, 0);
		helper.setBlock(Blocks.wool, 3, 15, -1, 15);
		helper.setBlock(Blocks.wool, 3, 15, -11, 0);
		helper.setBlock(Blocks.wool, 3, 15, -12, 0);
		helper.setBlock(Blocks.wool, 3, 15, 0, 0);
		helper.setBlock(Blocks.wool, 3, 16, -1, 0);
		helper.setBlock(Blocks.wool, 3, 16, -11, 0);
		helper.setBlock(Blocks.wool, 3, 17, -10, 0);
		helper.setBlock(Blocks.wool, 3, 17, -11, 0);
		helper.setBlock(Blocks.wool, 3, 17, -2, 15);
		helper.setBlock(Blocks.wool, 3, 8, -10, 15);
		helper.setBlock(Blocks.wool, 3, 8, -11, 15);
		helper.setBlock(Blocks.wool, 3, 8, -2, 15);
		helper.setBlock(Blocks.wool, 3, 9, -1, 15);
		helper.setBlock(Blocks.wool, 3, 9, -11, 0);
		helper.setBlock(Blocks.wool, 4, 10, -1, 15);
		helper.setBlock(Blocks.wool, 4, 10, -11, 15);
		helper.setBlock(Blocks.wool, 4, 11, -1, 15);
		helper.setBlock(Blocks.wool, 4, 11, -11, 15);
		helper.setBlock(Blocks.wool, 4, 12, -1, 0);
		helper.setBlock(Blocks.wool, 4, 12, -11, 15);
		helper.setBlock(Blocks.wool, 4, 13, -1, 0);
		helper.setBlock(Blocks.wool, 4, 13, -11, 15);
		helper.setBlock(Blocks.wool, 4, 14, -1, 0);
		helper.setBlock(Blocks.wool, 4, 14, -11, 0);
		helper.setBlock(Blocks.wool, 4, 15, -1, 0);
		helper.setBlock(Blocks.wool, 4, 15, -11, 0);
		helper.setBlock(Blocks.wool, 4, 16, -11, 0);
		helper.setBlock(Blocks.wool, 4, 17, -10, 0);
		helper.setBlock(Blocks.wool, 4, 17, -2, 0);
		helper.setBlock(Blocks.wool, 4, 9, -11, 15);
		helper.setBlock(Blocks.wool, 5, 10, -10, 0);
		helper.setBlock(Blocks.wool, 5, 10, -2, 15);
		helper.setBlock(Blocks.wool, 5, 11, -10, 15);
		helper.setBlock(Blocks.wool, 5, 11, -2, 0);
		helper.setBlock(Blocks.wool, 5, 12, -10, 15);
		helper.setBlock(Blocks.wool, 5, 12, -2, 0);
		helper.setBlock(Blocks.wool, 5, 13, -10, 0);
		helper.setBlock(Blocks.wool, 5, 13, -2, 0);
		helper.setBlock(Blocks.wool, 5, 14, -10, 0);
		helper.setBlock(Blocks.wool, 5, 14, -2, 15);
		helper.setBlock(Blocks.wool, 5, 15, -10, 0);
		helper.setBlock(Blocks.wool, 5, 15, -2, 0);
		helper.setBlock(Blocks.wool, 5, 16, -10, 15);
		helper.setBlock(Blocks.wool, 5, 16, -2, 0);
		helper.setBlock(Blocks.wool, 5, 17, -10, 0);
		helper.setBlock(Blocks.wool, 5, 17, -2, 0);
		helper.setBlock(Blocks.wool, 5, 8, -10, 0);
		helper.setBlock(Blocks.wool, 5, 8, -2, 0);
		helper.setBlock(Blocks.wool, 5, 9, -10, 0);
		helper.setBlock(Blocks.wool, 5, 9, -2, 15);
		helper.setChestAt(-1, 3, -11, rand());
		helper.setChestAt(-1, 3, -12, rand());
		helper.setChestAt(-1, 3, -14, rand());
		helper.setChestAt(-1, 3, -2, rand());
		helper.setChestAt(-1, 3, -3, rand());
		helper.setChestAt(-1, 3, -5, rand());
		helper.setChestAt(-1, 3, -6, rand());
		helper.setChestAt(-1, 3, -8, rand());
		helper.setChestAt(-1, 3, -9, rand());
		helper.setChestAt(-1, 3, 0, rand());
		helper.setChestAt(-1, 3, 1, rand());
		helper.setChestAt(-1, 3, 3, rand());
		helper.setChestAt(-1, 3, 4, rand());
		helper.setChestAt(-1, 3, 6, rand());
		helper.setChestAt(-1, 3, 7, rand());
		helper.setChestAt(2, 2, 10, rand());
		helper.setChestAt(5, 3, -11, rand());
		helper.setChestAt(5, 3, -12, rand());
		helper.setChestAt(5, 3, -14, rand());
		helper.setChestAt(5, 3, -2, rand());
		helper.setChestAt(5, 3, -3, rand());
		helper.setChestAt(5, 3, -5, rand());
		helper.setChestAt(5, 3, -6, rand());
		helper.setChestAt(5, 3, -8, rand());
		helper.setChestAt(5, 3, -9, rand());
		helper.setChestAt(5, 3, 0, rand());
		helper.setChestAt(5, 3, 1, rand());
		helper.setChestAt(5, 3, 3, rand());
		helper.setChestAt(5, 3, 4, rand());
		helper.setChestAt(5, 3, 6, rand());
		helper.setChestAt(5, 3, 7, rand());
		helper.setBlock(Blocks.wooden_slab, -1, 1, 10, 8);
		helper.setBlock(Blocks.wooden_slab, -1, 1, 11, 8);
		helper.setBlock(Blocks.wooden_slab, -1, 1, 12, 8);
		helper.setBlock(Blocks.wooden_slab, -1, 1, 5, 8);
		helper.setBlock(Blocks.wooden_slab, -1, 1, 6, 8);
		helper.setBlock(Blocks.wooden_slab, -1, 1, 7, 8);
		helper.setBlock(Blocks.wooden_slab, -1, 1, 9, 8);
		helper.setBlock(Blocks.wooden_slab, -1, 4, -1, 8);
		helper.setBlock(Blocks.wooden_slab, -1, 4, -10, 8);
		helper.setBlock(Blocks.wooden_slab, -1, 4, -11, 8);
		helper.setBlock(Blocks.wooden_slab, -1, 4, -12, 8);
		helper.setBlock(Blocks.wooden_slab, -1, 4, -13, 8);
		helper.setBlock(Blocks.wooden_slab, -1, 4, -14, 8);
		helper.setBlock(Blocks.wooden_slab, -1, 4, -2, 8);
		helper.setBlock(Blocks.wooden_slab, -1, 4, -3, 8);
		helper.setBlock(Blocks.wooden_slab, -1, 4, -4, 8);
		helper.setBlock(Blocks.wooden_slab, -1, 4, -5, 8);
		helper.setBlock(Blocks.wooden_slab, -1, 4, -6, 8);
		helper.setBlock(Blocks.wooden_slab, -1, 4, -7, 8);
		helper.setBlock(Blocks.wooden_slab, -1, 4, -8, 8);
		helper.setBlock(Blocks.wooden_slab, -1, 4, -9, 8);
		helper.setBlock(Blocks.wooden_slab, -1, 4, 0, 8);
		helper.setBlock(Blocks.wooden_slab, -1, 4, 1, 8);
		helper.setBlock(Blocks.wooden_slab, -1, 4, 10, 8);
		helper.setBlock(Blocks.wooden_slab, -1, 4, 11, 8);
		helper.setBlock(Blocks.wooden_slab, -1, 4, 12, 8);
		helper.setBlock(Blocks.wooden_slab, -1, 4, 2, 8);
		helper.setBlock(Blocks.wooden_slab, -1, 4, 3, 8);
		helper.setBlock(Blocks.wooden_slab, -1, 4, 4, 8);
		helper.setBlock(Blocks.wooden_slab, -1, 4, 5, 8);
		helper.setBlock(Blocks.wooden_slab, -1, 4, 6, 8);
		helper.setBlock(Blocks.wooden_slab, -1, 4, 7, 8);
		helper.setBlock(Blocks.wooden_slab, -1, 4, 9, 8);
		helper.setBlock(Blocks.wooden_slab, -2, 1, 10, 8);
		helper.setBlock(Blocks.wooden_slab, -2, 1, 11, 8);
		helper.setBlock(Blocks.wooden_slab, -2, 1, 9, 8);
		helper.setBlock(Blocks.wooden_slab, -2, 4, 10, 8);
		helper.setBlock(Blocks.wooden_slab, -2, 4, 11, 8);
		helper.setBlock(Blocks.wooden_slab, -2, 4, 12, 8);
		helper.setBlock(Blocks.wooden_slab, -2, 4, 9, 8);
		helper.setBlock(Blocks.wooden_slab, -3, 2, 10);
		helper.setBlock(Blocks.wooden_slab, -3, 2, 11);
		helper.setBlock(Blocks.wooden_slab, -3, 4, -1, 8);
		helper.setBlock(Blocks.wooden_slab, -3, 4, -10, 8);
		helper.setBlock(Blocks.wooden_slab, -3, 4, -11, 8);
		helper.setBlock(Blocks.wooden_slab, -3, 4, -12, 8);
		helper.setBlock(Blocks.wooden_slab, -3, 4, -2, 8);
		helper.setBlock(Blocks.wooden_slab, -3, 4, -3, 8);
		helper.setBlock(Blocks.wooden_slab, -3, 4, -4, 8);
		helper.setBlock(Blocks.wooden_slab, -3, 4, -5, 8);
		helper.setBlock(Blocks.wooden_slab, -3, 4, -6, 8);
		helper.setBlock(Blocks.wooden_slab, -3, 4, -7, 8);
		helper.setBlock(Blocks.wooden_slab, -3, 4, -8, 8);
		helper.setBlock(Blocks.wooden_slab, -3, 4, -9, 8);
		helper.setBlock(Blocks.wooden_slab, -3, 4, 0, 8);
		helper.setBlock(Blocks.wooden_slab, -3, 4, 1, 8);
		helper.setBlock(Blocks.wooden_slab, -3, 4, 10, 8);
		helper.setBlock(Blocks.wooden_slab, -3, 4, 11, 8);
		helper.setBlock(Blocks.wooden_slab, -3, 4, 2, 8);
		helper.setBlock(Blocks.wooden_slab, -3, 4, 3, 8);
		helper.setBlock(Blocks.wooden_slab, -3, 4, 4, 8);
		helper.setBlock(Blocks.wooden_slab, -3, 4, 5, 8);
		helper.setBlock(Blocks.wooden_slab, -3, 4, 6, 8);
		helper.setBlock(Blocks.wooden_slab, -3, 4, 7, 8);
		helper.setBlock(Blocks.wooden_slab, -3, 4, 8, 8);
		helper.setBlock(Blocks.wooden_slab, -3, 4, 9, 8);
		helper.setBlock(Blocks.wooden_slab, -4, 2, 10, 8);
		helper.setBlock(Blocks.wooden_slab, -4, 2, 11, 8);
		helper.setBlock(Blocks.wooden_slab, 0, 1, 12, 8);
		helper.setBlock(Blocks.wooden_slab, 0, 4, -1, 8);
		helper.setBlock(Blocks.wooden_slab, 0, 4, -11, 8);
		helper.setBlock(Blocks.wooden_slab, 0, 4, -12, 8);
		helper.setBlock(Blocks.wooden_slab, 0, 4, -13, 8);
		helper.setBlock(Blocks.wooden_slab, 0, 4, -14, 8);
		helper.setBlock(Blocks.wooden_slab, 0, 4, -15, 8);
		helper.setBlock(Blocks.wooden_slab, 0, 4, -3, 8);
		helper.setBlock(Blocks.wooden_slab, 0, 4, -4, 8);
		helper.setBlock(Blocks.wooden_slab, 0, 4, -5, 8);
		helper.setBlock(Blocks.wooden_slab, 0, 4, -6, 8);
		helper.setBlock(Blocks.wooden_slab, 0, 4, -7, 8);
		helper.setBlock(Blocks.wooden_slab, 0, 4, -8, 8);
		helper.setBlock(Blocks.wooden_slab, 0, 4, -9, 8);
		helper.setBlock(Blocks.wooden_slab, 0, 4, 0, 8);
		helper.setBlock(Blocks.wooden_slab, 0, 4, 1, 8);
		helper.setBlock(Blocks.wooden_slab, 0, 4, 10, 8);
		helper.setBlock(Blocks.wooden_slab, 0, 4, 11, 8);
		helper.setBlock(Blocks.wooden_slab, 0, 4, 12, 8);
		helper.setBlock(Blocks.wooden_slab, 0, 4, 2, 8);
		helper.setBlock(Blocks.wooden_slab, 0, 4, 3, 8);
		helper.setBlock(Blocks.wooden_slab, 0, 4, 4, 8);
		helper.setBlock(Blocks.wooden_slab, 0, 4, 5, 8);
		helper.setBlock(Blocks.wooden_slab, 0, 4, 6, 8);
		helper.setBlock(Blocks.wooden_slab, 0, 4, 7, 8);
		helper.setBlock(Blocks.wooden_slab, 0, 4, 9, 8);
		helper.setBlock(Blocks.wooden_slab, 0, 5, 6, 8);
		helper.setBlock(Blocks.wooden_slab, 0, 5, 7, 8);
		helper.setBlock(Blocks.wooden_slab, 0, 5, 8, 8);
		helper.setBlock(Blocks.wooden_slab, 0, 6, 6, 8);
		helper.setBlock(Blocks.wooden_slab, 0, 6, 7, 8);
		helper.setBlock(Blocks.wooden_slab, 0, 6, 8, 8);
		helper.setBlock(Blocks.wooden_slab, 0, 7, 6, 8);
		helper.setBlock(Blocks.wooden_slab, 0, 7, 7, 8);
		helper.setBlock(Blocks.wooden_slab, 0, 7, 8, 8);
		helper.setBlock(Blocks.wooden_slab, 0, 8, 5);
		helper.setBlock(Blocks.wooden_slab, 0, 8, 6);
		helper.setBlock(Blocks.wooden_slab, 0, 8, 7);
		helper.setBlock(Blocks.wooden_slab, 0, 8, 8);
		helper.setBlock(Blocks.wooden_slab, 0, 8, 9);
		helper.setBlock(Blocks.wooden_slab, 1, 1, -14, 8);
		helper.setBlock(Blocks.wooden_slab, 1, 4, -1, 8);
		helper.setBlock(Blocks.wooden_slab, 1, 4, -10, 8);
		helper.setBlock(Blocks.wooden_slab, 1, 4, -11, 8);
		helper.setBlock(Blocks.wooden_slab, 1, 4, -12, 8);
		helper.setBlock(Blocks.wooden_slab, 1, 4, -13, 8);
		helper.setBlock(Blocks.wooden_slab, 1, 4, -14, 8);
		helper.setBlock(Blocks.wooden_slab, 1, 4, -15, 8);
		helper.setBlock(Blocks.wooden_slab, 1, 4, -16, 8);
		helper.setBlock(Blocks.wooden_slab, 1, 4, -17, 8);
		helper.setBlock(Blocks.wooden_slab, 1, 4, -2, 8);
		helper.setBlock(Blocks.wooden_slab, 1, 4, -3, 8);
		helper.setBlock(Blocks.wooden_slab, 1, 4, -4, 8);
		helper.setBlock(Blocks.wooden_slab, 1, 4, -5, 8);
		helper.setBlock(Blocks.wooden_slab, 1, 4, -6, 8);
		helper.setBlock(Blocks.wooden_slab, 1, 4, -7, 8);
		helper.setBlock(Blocks.wooden_slab, 1, 4, -8, 8);
		helper.setBlock(Blocks.wooden_slab, 1, 4, -9, 8);
		helper.setBlock(Blocks.wooden_slab, 1, 4, 0, 8);
		helper.setBlock(Blocks.wooden_slab, 1, 4, 1, 8);
		helper.setBlock(Blocks.wooden_slab, 1, 4, 10, 8);
		helper.setBlock(Blocks.wooden_slab, 1, 4, 11, 8);
		helper.setBlock(Blocks.wooden_slab, 1, 4, 12, 8);
		helper.setBlock(Blocks.wooden_slab, 1, 4, 2, 8);
		helper.setBlock(Blocks.wooden_slab, 1, 4, 3, 8);
		helper.setBlock(Blocks.wooden_slab, 1, 4, 4, 8);
		helper.setBlock(Blocks.wooden_slab, 1, 4, 5, 8);
		helper.setBlock(Blocks.wooden_slab, 1, 4, 6, 8);
		helper.setBlock(Blocks.wooden_slab, 1, 4, 7, 8);
		helper.setBlock(Blocks.wooden_slab, 1, 4, 9, 8);
		helper.setBlock(Blocks.wooden_slab, 1, 6, -19);
		helper.setBlock(Blocks.wooden_slab, 1, 8, 5);
		helper.setBlock(Blocks.wooden_slab, 1, 8, 6);
		helper.setBlock(Blocks.wooden_slab, 1, 8, 7);
		helper.setBlock(Blocks.wooden_slab, 1, 8, 8);
		helper.setBlock(Blocks.wooden_slab, 1, 8, 9);
		helper.setBlock(Blocks.wooden_slab, 2, 4, -1, 8);
		helper.setBlock(Blocks.wooden_slab, 2, 4, -10, 8);
		helper.setBlock(Blocks.wooden_slab, 2, 4, -11, 8);
		helper.setBlock(Blocks.wooden_slab, 2, 4, -12, 8);
		helper.setBlock(Blocks.wooden_slab, 2, 4, -13, 8);
		helper.setBlock(Blocks.wooden_slab, 2, 4, -2, 8);
		helper.setBlock(Blocks.wooden_slab, 2, 4, -3, 8);
		helper.setBlock(Blocks.wooden_slab, 2, 4, -4, 8);
		helper.setBlock(Blocks.wooden_slab, 2, 4, -5, 8);
		helper.setBlock(Blocks.wooden_slab, 2, 4, -7, 8);
		helper.setBlock(Blocks.wooden_slab, 2, 4, -8, 8);
		helper.setBlock(Blocks.wooden_slab, 2, 4, -9, 8);
		helper.setBlock(Blocks.wooden_slab, 2, 4, 0, 8);
		helper.setBlock(Blocks.wooden_slab, 2, 4, 1, 8);
		helper.setBlock(Blocks.wooden_slab, 2, 4, 10, 8);
		helper.setBlock(Blocks.wooden_slab, 2, 4, 11, 8);
		helper.setBlock(Blocks.wooden_slab, 2, 4, 12, 8);
		helper.setBlock(Blocks.wooden_slab, 2, 4, 2, 8);
		helper.setBlock(Blocks.wooden_slab, 2, 4, 3, 8);
		helper.setBlock(Blocks.wooden_slab, 2, 4, 4, 8);
		helper.setBlock(Blocks.wooden_slab, 2, 4, 5, 8);
		helper.setBlock(Blocks.wooden_slab, 2, 4, 6, 8);
		helper.setBlock(Blocks.wooden_slab, 2, 4, 7, 8);
		helper.setBlock(Blocks.wooden_slab, 2, 6, -20);
		helper.setBlock(Blocks.wooden_slab, 2, 8, 5);
		helper.setBlock(Blocks.wooden_slab, 2, 8, 6);
		helper.setBlock(Blocks.wooden_slab, 2, 8, 7);
		helper.setBlock(Blocks.wooden_slab, 2, 8, 8);
		helper.setBlock(Blocks.wooden_slab, 2, 8, 9);
		helper.setBlock(Blocks.wooden_slab, 3, 1, -14, 8);
		helper.setBlock(Blocks.wooden_slab, 3, 4, -1, 8);
		helper.setBlock(Blocks.wooden_slab, 3, 4, -10, 8);
		helper.setBlock(Blocks.wooden_slab, 3, 4, -11, 8);
		helper.setBlock(Blocks.wooden_slab, 3, 4, -12, 8);
		helper.setBlock(Blocks.wooden_slab, 3, 4, -13, 8);
		helper.setBlock(Blocks.wooden_slab, 3, 4, -14, 8);
		helper.setBlock(Blocks.wooden_slab, 3, 4, -15, 8);
		helper.setBlock(Blocks.wooden_slab, 3, 4, -16, 8);
		helper.setBlock(Blocks.wooden_slab, 3, 4, -17, 8);
		helper.setBlock(Blocks.wooden_slab, 3, 4, -2, 8);
		helper.setBlock(Blocks.wooden_slab, 3, 4, -3, 8);
		helper.setBlock(Blocks.wooden_slab, 3, 4, -4, 8);
		helper.setBlock(Blocks.wooden_slab, 3, 4, -5, 8);
		helper.setBlock(Blocks.wooden_slab, 3, 4, -6, 8);
		helper.setBlock(Blocks.wooden_slab, 3, 4, -7, 8);
		helper.setBlock(Blocks.wooden_slab, 3, 4, -8, 8);
		helper.setBlock(Blocks.wooden_slab, 3, 4, -9, 8);
		helper.setBlock(Blocks.wooden_slab, 3, 4, 0, 8);
		helper.setBlock(Blocks.wooden_slab, 3, 4, 1, 8);
		helper.setBlock(Blocks.wooden_slab, 3, 4, 10, 8);
		helper.setBlock(Blocks.wooden_slab, 3, 4, 11, 8);
		helper.setBlock(Blocks.wooden_slab, 3, 4, 12, 8);
		helper.setBlock(Blocks.wooden_slab, 3, 4, 2, 8);
		helper.setBlock(Blocks.wooden_slab, 3, 4, 3, 8);
		helper.setBlock(Blocks.wooden_slab, 3, 4, 4, 8);
		helper.setBlock(Blocks.wooden_slab, 3, 4, 5, 8);
		helper.setBlock(Blocks.wooden_slab, 3, 4, 6, 8);
		helper.setBlock(Blocks.wooden_slab, 3, 4, 7, 8);
		helper.setBlock(Blocks.wooden_slab, 3, 6, -19);
		helper.setBlock(Blocks.wooden_slab, 3, 8, 5);
		helper.setBlock(Blocks.wooden_slab, 3, 8, 6);
		helper.setBlock(Blocks.wooden_slab, 3, 8, 7);
		helper.setBlock(Blocks.wooden_slab, 3, 8, 8);
		helper.setBlock(Blocks.wooden_slab, 3, 8, 9);
		helper.setBlock(Blocks.wooden_slab, 4, 1, 12, 8);
		helper.setBlock(Blocks.wooden_slab, 4, 4, -1, 8);
		helper.setBlock(Blocks.wooden_slab, 4, 4, -11, 8);
		helper.setBlock(Blocks.wooden_slab, 4, 4, -12, 8);
		helper.setBlock(Blocks.wooden_slab, 4, 4, -13, 8);
		helper.setBlock(Blocks.wooden_slab, 4, 4, -14, 8);
		helper.setBlock(Blocks.wooden_slab, 4, 4, -15, 8);
		helper.setBlock(Blocks.wooden_slab, 4, 4, -3, 8);
		helper.setBlock(Blocks.wooden_slab, 4, 4, -4, 8);
		helper.setBlock(Blocks.wooden_slab, 4, 4, -5, 8);
		helper.setBlock(Blocks.wooden_slab, 4, 4, -6, 8);
		helper.setBlock(Blocks.wooden_slab, 4, 4, -7, 8);
		helper.setBlock(Blocks.wooden_slab, 4, 4, -8, 8);
		helper.setBlock(Blocks.wooden_slab, 4, 4, -9, 8);
		helper.setBlock(Blocks.wooden_slab, 4, 4, 0, 8);
		helper.setBlock(Blocks.wooden_slab, 4, 4, 1, 8);
		helper.setBlock(Blocks.wooden_slab, 4, 4, 10, 8);
		helper.setBlock(Blocks.wooden_slab, 4, 4, 11, 8);
		helper.setBlock(Blocks.wooden_slab, 4, 4, 12, 8);
		helper.setBlock(Blocks.wooden_slab, 4, 4, 2, 8);
		helper.setBlock(Blocks.wooden_slab, 4, 4, 3, 8);
		helper.setBlock(Blocks.wooden_slab, 4, 4, 4, 8);
		helper.setBlock(Blocks.wooden_slab, 4, 4, 5, 8);
		helper.setBlock(Blocks.wooden_slab, 4, 4, 6, 8);
		helper.setBlock(Blocks.wooden_slab, 4, 4, 7, 8);
		helper.setBlock(Blocks.wooden_slab, 4, 4, 9, 8);
		helper.setBlock(Blocks.wooden_slab, 4, 5, 6, 8);
		helper.setBlock(Blocks.wooden_slab, 4, 5, 7, 8);
		helper.setBlock(Blocks.wooden_slab, 4, 5, 8, 8);
		helper.setBlock(Blocks.wooden_slab, 4, 6, 6, 8);
		helper.setBlock(Blocks.wooden_slab, 4, 6, 7, 8);
		helper.setBlock(Blocks.wooden_slab, 4, 6, 8, 8);
		helper.setBlock(Blocks.wooden_slab, 4, 7, 6, 8);
		helper.setBlock(Blocks.wooden_slab, 4, 7, 7, 8);
		helper.setBlock(Blocks.wooden_slab, 4, 7, 8, 8);
		helper.setBlock(Blocks.wooden_slab, 4, 8, 5);
		helper.setBlock(Blocks.wooden_slab, 4, 8, 6);
		helper.setBlock(Blocks.wooden_slab, 4, 8, 7);
		helper.setBlock(Blocks.wooden_slab, 4, 8, 8);
		helper.setBlock(Blocks.wooden_slab, 4, 8, 9);
		helper.setBlock(Blocks.wooden_slab, 5, 1, 10, 8);
		helper.setBlock(Blocks.wooden_slab, 5, 1, 11, 8);
		helper.setBlock(Blocks.wooden_slab, 5, 1, 12, 8);
		helper.setBlock(Blocks.wooden_slab, 5, 1, 5, 8);
		helper.setBlock(Blocks.wooden_slab, 5, 1, 6, 8);
		helper.setBlock(Blocks.wooden_slab, 5, 1, 7, 8);
		helper.setBlock(Blocks.wooden_slab, 5, 1, 9, 8);
		helper.setBlock(Blocks.wooden_slab, 5, 4, -1, 8);
		helper.setBlock(Blocks.wooden_slab, 5, 4, -10, 8);
		helper.setBlock(Blocks.wooden_slab, 5, 4, -11, 8);
		helper.setBlock(Blocks.wooden_slab, 5, 4, -12, 8);
		helper.setBlock(Blocks.wooden_slab, 5, 4, -13, 8);
		helper.setBlock(Blocks.wooden_slab, 5, 4, -14, 8);
		helper.setBlock(Blocks.wooden_slab, 5, 4, -2, 8);
		helper.setBlock(Blocks.wooden_slab, 5, 4, -3, 8);
		helper.setBlock(Blocks.wooden_slab, 5, 4, -4, 8);
		helper.setBlock(Blocks.wooden_slab, 5, 4, -5, 8);
		helper.setBlock(Blocks.wooden_slab, 5, 4, -6, 8);
		helper.setBlock(Blocks.wooden_slab, 5, 4, -7, 8);
		helper.setBlock(Blocks.wooden_slab, 5, 4, -8, 8);
		helper.setBlock(Blocks.wooden_slab, 5, 4, -9, 8);
		helper.setBlock(Blocks.wooden_slab, 5, 4, 0, 8);
		helper.setBlock(Blocks.wooden_slab, 5, 4, 1, 8);
		helper.setBlock(Blocks.wooden_slab, 5, 4, 10, 8);
		helper.setBlock(Blocks.wooden_slab, 5, 4, 11, 8);
		helper.setBlock(Blocks.wooden_slab, 5, 4, 12, 8);
		helper.setBlock(Blocks.wooden_slab, 5, 4, 2, 8);
		helper.setBlock(Blocks.wooden_slab, 5, 4, 3, 8);
		helper.setBlock(Blocks.wooden_slab, 5, 4, 4, 8);
		helper.setBlock(Blocks.wooden_slab, 5, 4, 5, 8);
		helper.setBlock(Blocks.wooden_slab, 5, 4, 6, 8);
		helper.setBlock(Blocks.wooden_slab, 5, 4, 7, 8);
		helper.setBlock(Blocks.wooden_slab, 5, 4, 9, 8);
		helper.setBlock(Blocks.wooden_slab, 6, 1, 10, 8);
		helper.setBlock(Blocks.wooden_slab, 6, 1, 11, 8);
		helper.setBlock(Blocks.wooden_slab, 6, 1, 9, 8);
		helper.setBlock(Blocks.wooden_slab, 6, 4, 10, 8);
		helper.setBlock(Blocks.wooden_slab, 6, 4, 11, 8);
		helper.setBlock(Blocks.wooden_slab, 6, 4, 12, 8);
		helper.setBlock(Blocks.wooden_slab, 6, 4, 9, 8);
		helper.setBlock(Blocks.wooden_slab, 7, 2, -1, 8);
		helper.setBlock(Blocks.wooden_slab, 7, 2, -2, 8);
		helper.setBlock(Blocks.wooden_slab, 7, 2, 0, 8);
		helper.setBlock(Blocks.wooden_slab, 7, 2, 1, 8);
		helper.setBlock(Blocks.wooden_slab, 7, 2, 10);
		helper.setBlock(Blocks.wooden_slab, 7, 2, 11);
		helper.setBlock(Blocks.wooden_slab, 7, 2, 2, 8);
		helper.setBlock(Blocks.wooden_slab, 7, 2, 3, 8);
		helper.setBlock(Blocks.wooden_slab, 7, 2, 4, 8);
		helper.setBlock(Blocks.wooden_slab, 7, 2, 5, 8);
		helper.setBlock(Blocks.wooden_slab, 7, 2, 6, 8);
		helper.setBlock(Blocks.wooden_slab, 7, 2, 7, 8);
		helper.setBlock(Blocks.wooden_slab, 7, 4, -1, 8);
		helper.setBlock(Blocks.wooden_slab, 7, 4, -10, 8);
		helper.setBlock(Blocks.wooden_slab, 7, 4, -11, 8);
		helper.setBlock(Blocks.wooden_slab, 7, 4, -12, 8);
		helper.setBlock(Blocks.wooden_slab, 7, 4, -2, 8);
		helper.setBlock(Blocks.wooden_slab, 7, 4, -3, 8);
		helper.setBlock(Blocks.wooden_slab, 7, 4, -4, 8);
		helper.setBlock(Blocks.wooden_slab, 7, 4, -5, 8);
		helper.setBlock(Blocks.wooden_slab, 7, 4, -6, 8);
		helper.setBlock(Blocks.wooden_slab, 7, 4, -7, 8);
		helper.setBlock(Blocks.wooden_slab, 7, 4, -8, 8);
		helper.setBlock(Blocks.wooden_slab, 7, 4, -9, 8);
		helper.setBlock(Blocks.wooden_slab, 7, 4, 0, 8);
		helper.setBlock(Blocks.wooden_slab, 7, 4, 1, 8);
		helper.setBlock(Blocks.wooden_slab, 7, 4, 10, 8);
		helper.setBlock(Blocks.wooden_slab, 7, 4, 11, 8);
		helper.setBlock(Blocks.wooden_slab, 7, 4, 2, 8);
		helper.setBlock(Blocks.wooden_slab, 7, 4, 3, 8);
		helper.setBlock(Blocks.wooden_slab, 7, 4, 4, 8);
		helper.setBlock(Blocks.wooden_slab, 7, 4, 5, 8);
		helper.setBlock(Blocks.wooden_slab, 7, 4, 6, 8);
		helper.setBlock(Blocks.wooden_slab, 7, 4, 7, 8);
		helper.setBlock(Blocks.wooden_slab, 7, 4, 8, 8);
		helper.setBlock(Blocks.wooden_slab, 7, 4, 9, 8);
		helper.setBlock(Blocks.wooden_slab, 8, 2, 10, 8);
		helper.setBlock(Blocks.wooden_slab, 8, 2, 11, 8);
		helper.setBlock(Blocks.redstone_wire, -1, 2, 11);
		helper.setBlock(Blocks.redstone_wire, -2, 2, 10);
		helper.setBlock(Blocks.redstone_wire, -2, 2, 11);
		helper.setBlock(Blocks.redstone_wire, -2, 2, 9);
		helper.setBlock(Blocks.redstone_wire, -3, 3, -1);
		helper.setBlock(Blocks.redstone_wire, -3, 3, -2);
		helper.setBlock(Blocks.redstone_wire, -3, 3, 0);
		helper.setBlock(Blocks.redstone_wire, -3, 3, 1);
		helper.setBlock(Blocks.redstone_wire, -3, 3, 2);
		helper.setBlock(Blocks.redstone_wire, -3, 3, 3);
		helper.setBlock(Blocks.redstone_wire, -3, 3, 4);
		helper.setBlock(Blocks.redstone_wire, -3, 3, 5);
		helper.setBlock(Blocks.redstone_wire, -3, 3, 6);
		helper.setBlock(Blocks.redstone_wire, -3, 3, 8);
		helper.setBlock(Blocks.redstone_wire, -3, 3, 9);
		helper.setBlock(Blocks.redstone_wire, 0, 2, 11);
		helper.setBlock(Blocks.redstone_wire, 1, 2, 11);
		helper.setBlock(Blocks.redstone_wire, 1, 3, 10);
		helper.setBlock(Blocks.redstone_wire, 2, 2, 11);
		helper.setBlock(Blocks.redstone_wire, 3, 2, 11);
		helper.setBlock(Blocks.redstone_wire, 4, 2, 11);
		helper.setBlock(Blocks.redstone_wire, 5, 2, 11);
		helper.setBlock(Blocks.redstone_wire, 6, 2, 10);
		helper.setBlock(Blocks.redstone_wire, 6, 2, 11);
		helper.setBlock(Blocks.redstone_wire, 6, 2, 9);
		helper.setBlock(Blocks.redstone_wire, 7, 3, -1);
		helper.setBlock(Blocks.redstone_wire, 7, 3, -2);
		helper.setBlock(Blocks.redstone_wire, 7, 3, 0);
		helper.setBlock(Blocks.redstone_wire, 7, 3, 1);
		helper.setBlock(Blocks.redstone_wire, 7, 3, 2);
		helper.setBlock(Blocks.redstone_wire, 7, 3, 3);
		helper.setBlock(Blocks.redstone_wire, 7, 3, 4);
		helper.setBlock(Blocks.redstone_wire, 7, 3, 5);
		helper.setBlock(Blocks.redstone_wire, 7, 3, 7);
		helper.setBlock(Blocks.redstone_wire, 7, 3, 8);
		helper.setBlock(Blocks.redstone_wire, 7, 3, 9);
		helper.setBlock(Blocks.unpowered_repeater, -3, 3, 7, 12);
		helper.setBlock(Blocks.unpowered_repeater, 7, 3, 6, 12);
		helper.setBlock(Blocks.iron_door, 2, 2, 9, 1);
		helper.setBlock(Blocks.iron_door, 2, 3, 9, 8);
		helper.setBlock(Blocks.iron_door, 2, 5, 4, 1);
		helper.setBlock(Blocks.iron_door, 2, 6, 4, 8);
		helper.setBlock(Blocks.ladder, 2, 10, -7, 2);
		helper.setBlock(Blocks.ladder, 2, 11, -7, 2);
		helper.setBlock(Blocks.ladder, 2, 12, -7, 2);
		helper.setBlock(Blocks.ladder, 2, 13, -7, 2);
		helper.setBlock(Blocks.ladder, 2, 14, -7, 2);
		helper.setBlock(Blocks.ladder, 2, 15, -7, 2);
		helper.setBlock(Blocks.ladder, 2, 16, -7, 2);
		helper.setBlock(Blocks.ladder, 2, 17, -7, 2);
		helper.setBlock(Blocks.ladder, 2, 18, -7, 2);
		helper.setBlock(Blocks.ladder, 2, 19, -7, 2);
		helper.setBlock(Blocks.ladder, 2, 20, -7, 2);
		helper.setBlock(Blocks.ladder, 2, 21, -7, 2);
		helper.setBlock(Blocks.ladder, 2, 22, -7, 2);
		helper.setBlock(Blocks.ladder, 2, 23, -7, 2);
		helper.setBlock(Blocks.ladder, 2, 5, -7, 2);
		helper.setBlock(Blocks.ladder, 2, 6, -7, 2);
		helper.setBlock(Blocks.ladder, 2, 7, -7, 2);
		helper.setBlock(Blocks.ladder, 2, 8, -7, 2);
		helper.setBlock(Blocks.ladder, 2, 9, -7, 2);
		helper.setBlock(Blocks.lever, 1, 3, 8, 4);
		helper.setBlock(Blocks.lever, 1, 6, 3, 4);
		return true;
	}

	private ChestType rand()
	{
		return ChestType.values()[Rand.nextInt(ChestType.values().length)];
	}
}
